<robot name="X02C-22dof">

  <mujoco>
    <compiler meshdir="./meshes" discardvisual="false" />
  </mujoco>
  <!-- <link name="world"></link>
  <joint name="pelvis" type="floating">
    <parent link="world" />
    <child link="pelvis" />
  </joint>-->
  <link name="pelvis">
    <inertial>
      <origin xyz="-1.0007E-18 -6.9124E-19 -0.047022" rpy="0 0 0" />
      <mass value="0.05" />
      <inertia ixx="0.0007894" ixy="2.4776E-20" ixz="-4.6732E-20" iyy="0.0007894" iyz="-1.7565E-20" izz="0.00061446" />
    </inertial>
    <visual>
      <origin xyz="0 0 0" rpy="0 0 0" />
      <geometry>
        <mesh filename="meshes/pelvis.STL" />
      </geometry>
      <material name="">
        <color rgba="0.45 0.45 0.45 1" />
      </material>
    </visual>
    <collision>
      <origin xyz="0 0 0" rpy="0 0 0" />
      <geometry>
        <mesh filename="meshes/pelvis.STL" />
      </geometry>
    </collision>
  </link>
  <link name="left_hip_yaw_link">
    <inertial>
      <origin xyz="0 0.01345995 0.04464151" rpy="0 0 0" />
      <mass value="1.741" />
      <inertia ixx="0.00652010" ixy="0.00000000" ixz="0.00000000" iyy="0.00470139" iyz="0.00093927" izz="0.00331528" />
    </inertial>
    <visual>
      <origin xyz="0 0 0" rpy="0 0 0" />
      <geometry>
        <mesh filename="meshes/left_hip_yaw_link.STL" />
      </geometry>
      <material name="">
        <color rgba="0.41961 0.41961 0.41961 1" />
      </material>
    </visual>
  </link>
  <joint name="left_hip_yaw_joint" type="revolute">
    <origin xyz="0 0 -0.1315" rpy="0 0 0" />
    <parent link="pelvis" />
    <child link="left_hip_yaw_link" />
    <axis xyz="0 0 1" />
    <limit lower="-0.393" upper="0.393" effort="50" velocity="51" />
  </joint>
  <link name="left_hip_roll_link">
    <inertial>
      <origin xyz="-0.034584 0.00017707 -0.071764" rpy="0 0 0" />
      <mass value="2.667" />
      <inertia ixx="0.00982457" ixy="0.00001637" ixz="-0.00165599" iyy="0.01129357" iyz="0.00003469" izz="0.00732501" />
    </inertial>
    <visual>
      <origin xyz="0 0 0" rpy="0 0 0" />
      <geometry>
        <mesh filename="meshes/left_hip_roll_link.STL" />
      </geometry>
      <material name="">
        <color rgba="0.41961 0.41961 0.41961 1" />
      </material>
    </visual>
    <collision>
      <origin xyz="0 0 0" rpy="0 0 0" />
      <geometry>
        <mesh filename="meshes/left_hip_roll_link.STL" />
      </geometry>
    </collision>
  </link>
  <joint name="left_hip_roll_joint" type="revolute">
    <origin xyz="0 0.12 -0.001" rpy="0 0 0" />
    <parent link="left_hip_yaw_link" />
    <child link="left_hip_roll_link" />
    <axis xyz="1 0 0" />
    <limit lower="-0.349" upper="0.534" effort="100" velocity="31" />
  </joint>
  <link name="left_hip_pitch_link">
    <inertial>
      <origin xyz="0.0082287 0 -0.16703084" rpy="0 0 0" />
      <mass value="1.8" />
      <inertia ixx="0.01698928" ixy="0.00000000" ixz="-0.00060774" iyy="0.01770562" iyz="-0.00000002" izz="0.00318692" />
    </inertial>
    <visual>
      <origin xyz="0 0 0" rpy="0 0 0" />
      <geometry>
        <mesh filename="meshes/left_hip_pitch_link.STL" />
      </geometry>
      <material name="">
        <color rgba="1.43 1.43 1.43 1" />
      </material>
    </visual>
    <collision>
      <origin xyz="0 0 0" rpy="0 0 0" />
      <geometry>
        <mesh filename="meshes/left_hip_pitch_link.STL" />
      </geometry>
    </collision>
  </link>
  <joint name="left_hip_pitch_joint" type="revolute">
    <origin xyz="0 0 -0.11" rpy="0 0 0" />
    <parent link="left_hip_roll_link" />
    <child link="left_hip_pitch_link" />
    <axis xyz="0 1 0" />
    <limit lower="-2.094" upper="0.534" effort="212" velocity="58.7" />
  </joint>
  <link name="left_knee_link">
    <inertial>
      <origin xyz="0.00111166 0 -0.14609747" rpy="0 0 0" />
      <mass value="1.125" />
      <inertia ixx="0.01158049" ixy="0.00000000" ixz="0.00032335" iyy="0.01172026" iyz="-0.00000001" izz="0.00121827" />
    </inertial>
    <visual>
      <origin xyz="0 0 0" rpy="0 0 0" />
      <geometry>
        <mesh filename="meshes/left_knee_link.STL" />
      </geometry>
      <material name="">
        <color rgba="1.43 1.43 1.43 1" />
      </material>
    </visual>
    <collision>
      <origin xyz="0 0 0" rpy="0 0 0" />
      <geometry>
        <mesh filename="meshes/left_knee_link.STL" />
      </geometry>
    </collision>
  </link>
  <joint name="left_knee_joint" type="revolute">
    <origin xyz="0 0 -0.35" rpy="0 0 0" />
    <parent link="left_hip_pitch_link" />
    <child link="left_knee_link" />
    <axis xyz="0 1 0" />
    <limit lower="0" upper="2.269" effort="93" velocity="150" />
  </joint>
  <link name="left_ankle_pitch_link">
    <inertial>
      <origin xyz="0 0 -0.03720405" rpy="0 0 0" />
      <mass value="0.2" />
      <inertia ixx="0.000193480443387712" ixy="1.77346258645289E-21" ixz="1.8701971487315E-17" iyy="0.000212196305121686" iyz="-4.94858303884928E-20" izz="7.03112206534629E-05" />
    </inertial>
    <visual>
      <origin xyz="0 0 0" rpy="0 0 0" />
      <geometry>
        <mesh filename="meshes/left_ankle_pitch_link.STL" />
      </geometry>
      <material name="">
        <color rgba="0.419607843137255 0.419607843137255 0.419607843137255 1" />
      </material>
    </visual>
    <collision>
      <origin xyz="0 0 0" rpy="0 0 0" />
      <geometry>
        <mesh filename="meshes/left_ankle_pitch_link.STL" />
      </geometry>
    </collision>
  </link>
  <joint name="left_ankle_pitch_joint" type="revolute">
    <origin xyz="0 0 -0.35" rpy="0 0 0" />
    <parent link="left_knee_link" />
    <child link="left_ankle_pitch_link" />
    <axis xyz="0 1 0" />
    <limit lower="-1.047" upper="1.047" effort="64.8" velocity="216.66" />
  </joint>
  <link name="left_ankle_roll_link">
    <inertial>
      <origin xyz="0.04871205 -0.00000742 -0.00856332" rpy="0 0 0" />
      <mass value="1" />
      <inertia ixx="0.00078296" ixy="-4.7701E-08" ixz="0.00031141" iyy="0.0065554" iyz="5.4255E-09" izz="0.0070348" />
    </inertial>
    <visual>
      <origin xyz="0 0 0" rpy="0 0 0" />
      <geometry>
        <mesh filename="meshes/left_ankle_roll_link.STL" />
      </geometry>
      <material name="">
        <color rgba="1.43 1.43 1.43 1" />
      </material>
    </visual>
    <collision><origin xyz="-0.085  0 -0.036"/><geometry><sphere radius="0.005"/></geometry></collision>
    <collision><origin xyz="-0.035  0.034 -0.036"/><geometry><sphere radius="0.005"/></geometry></collision>
    <collision><origin xyz="-0.035 -0.034 -0.036"/><geometry><sphere radius="0.005"/></geometry></collision>
    <collision><origin xyz="0.12    0.045 -0.036"/><geometry><sphere radius="0.005"/></geometry></collision>
    <collision><origin xyz="0.12   -0.045 -0.036"/><geometry><sphere radius="0.005"/></geometry></collision>
    <collision><origin xyz="0.18  0  -0.036"/><geometry><sphere radius="0.005"/></geometry></collision>
    <collision>
            <origin xyz="0.08 -0.026 -0.024" rpy="0 1.5708 0"/>
            <geometry>
                <cylinder radius="0.01" length="0.1"/>
            </geometry>
    </collision>
    <collision>
            <origin xyz="0.044 -0.018 -0.024" rpy="0 -1.5708 0"/>
            <geometry>
                <cylinder radius="0.01" length="0.2"/>
            </geometry>
    </collision>
    <collision>
            <origin xyz="0.046 -0.01 -0.024" rpy="0 -1.5708 0"/>
            <geometry>
                <cylinder radius="0.01" length="0.24"/>
            </geometry>
    </collision>
    <collision>
            <origin xyz="0.048 0 -0.024" rpy="0 -1.5708 0"/>
            <geometry>
                <cylinder radius="0.01" length="0.25"/>
            </geometry>
    </collision>
    <collision>
            <origin xyz="0.046 0.01 -0.024" rpy="0 -1.5708 0"/>
            <geometry>
                <cylinder radius="0.01" length="0.24"/>
            </geometry>
    </collision>
    <collision>
            <origin xyz="0.044 0.018 -0.024" rpy="0 -1.5708 0"/>
            <geometry>
                <cylinder radius="0.01" length="0.2"/>
            </geometry>
    </collision>
    <collision>
            <origin xyz="0.08 0.026 -0.024" rpy="0 1.5708 0"/>
            <geometry>
                <cylinder radius="0.01" length="0.1"/>
            </geometry>
    </collision>
  </link>
  <joint name="left_ankle_roll_joint" type="revolute">
    <origin xyz="0 0 -0.058" rpy="0 0 0" />
    <parent link="left_ankle_pitch_link" />
    <child link="left_ankle_roll_link" />
    <axis xyz="1 0 0" />
    <limit lower="-0.5236" upper="0.5236" effort="7.7" velocity="20" />
  </joint>
  <link name="right_hip_yaw_link">
    <inertial>
      <origin xyz="0 -0.050494 0.006108" rpy="0 0 0" />
      <mass value="0.947" />
      <inertia ixx="0.00267262" ixy="0.00000000" ixz="0.00000000" iyy="0.00076622" iyz="0.000070555" izz="0.00231603" />
    </inertial>
    <visual>
      <origin xyz="0 0 0" rpy="0 0 0" />
      <geometry>
        <mesh filename="meshes/right_hip_yaw_link.STL" />
      </geometry>
      <material name="">
        <color rgba="0.41961 0.41961 0.41961 1" />
      </material>
    </visual>
  </link>
  <joint name="right_hip_yaw_joint" type="revolute">
    <origin xyz="0 0 -0.1315" rpy="0 0 0" />
    <parent link="pelvis" />
    <child link="right_hip_yaw_link" />
    <axis xyz="0 0 1" />
    <limit lower="-0.393" upper="0.393" effort="50" velocity="51" />
  </joint>
  <link name="right_hip_roll_link">
    <inertial>
      <origin xyz="-0.034584 -0.00017759 -0.071763" rpy="0 0 0" />
      <mass value="2.667" />
      <inertia ixx="0.00982480" ixy="-0.00001634" ixz="-0.00165597" iyy="0.01129380" iyz="-0.00003463" izz="0.00732491" />
    </inertial>
    <visual>
      <origin xyz="0 0 0" rpy="0 0 0" />
      <geometry>
        <mesh filename="meshes/right_hip_roll_link.STL" />
      </geometry>
      <material name="">
        <color rgba="0.41961 0.41961 0.41961 1" />
      </material>
    </visual>
    <collision>
      <origin xyz="0 0 0" rpy="0 0 0" />
      <geometry>
        <mesh filename="meshes/right_hip_roll_link.STL" />
      </geometry>
    </collision>
  </link>
  <joint name="right_hip_roll_joint" type="revolute">
    <origin xyz="0 -0.12 -0.001" rpy="0 0 0" />
    <parent link="right_hip_yaw_link" />
    <child link="right_hip_roll_link" />
    <axis xyz="1 0 0" />
    <limit lower="-0.534" upper="0.349" effort="100" velocity="31" />
  </joint>
  <link name="right_hip_pitch_link">
    <inertial>
      <origin xyz="0.0082287 0 -0.16703110" rpy="0 0 0" />
      <mass value="1.8" />
      <inertia ixx="0.01698931" ixy="0.00000000" ixz="-0.00060774" iyy="0.01770564" iyz="-0.00000004" izz="0.00318691" />
    </inertial>
    <visual>
      <origin xyz="0 0 0" rpy="0 0 0" />
      <geometry>
        <mesh filename="meshes/right_hip_pitch_link.STL" />
      </geometry>
      <material name="">
        <color rgba="1.43 1.43 1.43 1" />
      </material>
    </visual>
    <collision>
      <origin xyz="0 0 0" rpy="0 0 0" />
      <geometry>
        <mesh filename="meshes/right_hip_pitch_link.STL" />
      </geometry>
    </collision>
  </link>
  <joint name="right_hip_pitch_joint" type="revolute">
    <origin xyz="0 0 -0.11" rpy="0 0 0" />
    <parent link="right_hip_roll_link" />
    <child link="right_hip_pitch_link" />
    <axis xyz="0 1 0" />
    <limit lower="-2.094" upper="0.534" effort="212" velocity="58.7" />
  </joint>
  <link name="right_knee_link">
    <inertial>
      <origin xyz="0.00111164 0 -0.14609739" rpy="0 0 0" />
      <mass value="1.125" />
      <inertia ixx="0.01158055" ixy="0.00000000" ixz="0.00032334" iyy="0.01172033" iyz="-0.00000001" izz="0.00121827" />
    </inertial>
    <visual>
      <origin xyz="0 0 0" rpy="0 0 0" />
      <geometry>
        <mesh filename="meshes/right_knee_link.STL" />
      </geometry>
      <material name="">
        <color rgba="1.43 1.43 1.43 1" />
      </material>
    </visual>
    <collision>
      <origin xyz="0 0 0" rpy="0 0 0" />
      <geometry>
        <mesh filename="meshes/right_knee_link.STL" />
      </geometry>
    </collision>
  </link>
  <joint name="right_knee_joint" type="revolute">
    <origin xyz="0 0 -0.35" rpy="0 0 0" />
    <parent link="right_hip_pitch_link" />
    <child link="right_knee_link" />
    <axis xyz="0 1 0" />
    <limit lower="0" upper="2.269" effort="93" velocity="150" />
  </joint>
  <link name="right_ankle_pitch_link">
    <inertial>
      <origin xyz="0 0 -0.03720405" rpy="0 0 0" />
      <mass value="0.2" />
      <inertia ixx="0.000193480443387716" ixy="8.18429100191069E-21" ixz="1.87984204635664E-17" iyy="0.00021219630512169" iyz="-7.24048296482114E-20" izz="7.03112206534629E-05" />
    </inertial>
    <visual>
      <origin xyz="0 0 0" rpy="0 0 0" />
      <geometry>
        <mesh filename="meshes/right_ankle_pitch_link.STL" />
      </geometry>
      <material name="">
        <color rgba="0.419607843137255 0.419607843137255 0.419607843137255 1" />
      </material>
    </visual>
    <collision>
      <origin xyz="0 0 0" rpy="0 0 0" />
      <geometry>
        <mesh filename="meshes/right_ankle_pitch_link.STL" />
      </geometry>
    </collision>
  </link>
  <joint name="right_ankle_pitch_joint" type="revolute">
    <origin xyz="0 0 -0.35" rpy="0 0 0" />
    <parent link="right_knee_link" />
    <child link="right_ankle_pitch_link" />
    <axis xyz="0 1 0" />
    <limit lower="-1.047" upper="1.047" effort="64.8" velocity="216.66" />
  </joint>
  <link name="right_ankle_roll_link">
    <inertial>
      <origin xyz="0.04871205 -0.00000742 -0.00856332" rpy="0 0 0" />
      <mass value="1" />
      <inertia ixx="0.000782962583512438" ixy="-4.76211443387741E-08" ixz="0.000311406184530333" iyy="0.00655536295881039" iyz="5.43640997216812E-09" izz="0.00703478064353501" />
    </inertial>
    <visual>
      <origin xyz="0 0 0" rpy="0 0 0" />
      <geometry>
        <mesh filename="meshes/right_ankle_roll_link.STL" />
      </geometry>
      <material name="">
        <color rgba="1.43 1.43 1.43 1" />
      </material>
    </visual>
    <collision><origin xyz="-0.085  0 -0.036"/><geometry><sphere radius="0.005"/></geometry></collision>
    <collision><origin xyz="-0.035  0.034 -0.036"/><geometry><sphere radius="0.005"/></geometry></collision>
    <collision><origin xyz="-0.035 -0.034 -0.036"/><geometry><sphere radius="0.005"/></geometry></collision>
    <collision><origin xyz="0.12    0.045 -0.036"/><geometry><sphere radius="0.005"/></geometry></collision>
    <collision><origin xyz="0.12   -0.045 -0.036"/><geometry><sphere radius="0.005"/></geometry></collision>
    <collision><origin xyz="0.18  0  -0.036"/><geometry><sphere radius="0.005"/></geometry></collision>
    <collision>
            <origin xyz="0.08 -0.026 -0.024" rpy="0 1.5708 0"/>
            <geometry>
                <cylinder radius="0.01" length="0.1"/>
            </geometry>
    </collision>
    <collision>
            <origin xyz="0.044 -0.018 -0.024" rpy="0 -1.5708 0"/>
            <geometry>
                <cylinder radius="0.01" length="0.2"/>
            </geometry>
    </collision>
    <collision>
            <origin xyz="0.046 -0.01 -0.024" rpy="0 -1.5708 0"/>
            <geometry>
                <cylinder radius="0.01" length="0.24"/>
            </geometry>
    </collision>
    <collision>
            <origin xyz="0.048 0 -0.024" rpy="0 -1.5708 0"/>
            <geometry>
                <cylinder radius="0.01" length="0.25"/>
            </geometry>
    </collision>
    <collision>
            <origin xyz="0.046 0.01 -0.024" rpy="0 -1.5708 0"/>
            <geometry>
                <cylinder radius="0.01" length="0.24"/>
            </geometry>
    </collision>
    <collision>
            <origin xyz="0.044 0.018 -0.024" rpy="0 -1.5708 0"/>
            <geometry>
                <cylinder radius="0.01" length="0.2"/>
            </geometry>
    </collision>
    <collision>
            <origin xyz="0.08 0.026 -0.024" rpy="0 1.5708 0"/>
            <geometry>
                <cylinder radius="0.01" length="0.1"/>
            </geometry>
    </collision>
  </link>
  <joint name="right_ankle_roll_joint" type="revolute">
    <origin xyz="0 0 -0.058" rpy="0 0 0" />
    <parent link="right_ankle_pitch_link" />
    <child link="right_ankle_roll_link" />
    <axis xyz="1 0 0" />
    <limit lower="-0.5236" upper="0.5236" effort="7.7" velocity="20" />
  </joint>
  <link name="torso_link">
    <inertial>
      <origin xyz="-0.00504342 -0.00000342 0.21297308" rpy="0 0 0" />
      <mass value="11" />
      <inertia ixx="0.29766308" ixy="-0.0000005" ixz="-0.00360754" iyy="0.27862266" iyz="0.0000039" izz="0.09552069" />
    </inertial>
    <visual>
      <origin xyz="0 0 0" rpy="0 0 0" />
      <geometry>
        <mesh filename="meshes/torso_link.STL" />
      </geometry>
      <material name="">
        <color rgba="1.43 1.43 1.43 1" />
      </material>
    </visual>
    <collision>
      <origin xyz="0 0 0" rpy="0 0 0" />
      <geometry>
        <mesh filename="meshes/torso_link.STL" />
      </geometry>
    </collision>
  </link>
  <joint name="torso" type="fixed">
    <origin xyz="0 0 0" rpy="0 0 0" />
    <parent link="pelvis" />
    <child link="torso_link" />
    <axis xyz="0 0 0" />
  </joint>
  <!-- LOGO -->
  <link name="logo_link">
    <visual>
      <origin xyz="0 0 0" rpy="0 0 0" />
      <geometry>
        <mesh filename="meshes/logo_link.STL" />
      </geometry>
      <material name="">
        <color rgba="0 0 0 1" />
      </material>
    </visual>
  </link>
  <joint name="logo_joint" type="fixed">
    <origin xyz="0 0 0" rpy="0 0 0" />
    <parent link="torso_link" />
    <child link="logo_link" />
    <axis xyz="0 0 0" />
  </joint>
  <!-- Head -->
  <link name="LiDARhead_link">
    <inertial>
      <origin xyz="0.02304564 0 0.20097708" rpy="0 0 0" />
      <mass value="2" />
      <inertia ixx="0.00600845" ixy="0" ixz="0.00027683" iyy="0.00669709" iyz="0.00000003" izz="0.00330564" />
    </inertial>
    <visual>
      <origin xyz="0 0 0" rpy="0 0 0" />
      <geometry>
        <mesh filename="meshes/LiDARhead_link.STL" />
      </geometry>
      <material name="">
        <color rgba="1 1 1 1" />
      </material>
    </visual>
    <collision>
      <origin xyz="0 0 0" rpy="0 0 0" />
      <geometry>
        <mesh filename="meshes/LiDARhead_link.STL" />
      </geometry>
    </collision>
  </link>
  <joint name="LiDARhead_joint" type="fixed">
    <origin xyz="-0.01 0 0.3575" rpy="0 0 0" />
    <parent link="torso_link" />
    <child link="LiDARhead_link" />
    <axis xyz="0 0 0" />
  </joint>
  <link name="left_shoulder_pitch_link">
    <inertial>
      <origin xyz="0 0.02913267 0" rpy="0 0 0" />
      <mass value="0.276" />
      <inertia ixx="0.00019627" ixy="0" ixz="0" iyy="0.00021249" iyz="0" izz="0.00033854" />
    </inertial>
    <visual>
      <origin xyz="0 0 0" rpy="0 0 0" />
      <geometry>
        <mesh filename="meshes/left_shoulder_pitch_link.STL" />
      </geometry>
      <material name="">
        <color rgba="0.419607843137255 0.419607843137255 0.419607843137255 1" />
      </material>
    </visual>
    <!-- <collision>
      <origin xyz="0 0 0" rpy="0 0 0" />
      <geometry>
        <mesh filename="meshes/left_shoulder_pitch_link.STL" />
      </geometry>
    </collision> -->
  </link>
  <joint name="left_shoulder_pitch_joint" type="revolute">
    <origin xyz="-0.01 0.13365 0.31135" rpy="0.17453 0 0" />
    <parent link="torso_link" />
    <child link="left_shoulder_pitch_link" />
    <axis xyz="0 1 0" />
    <limit lower="-2.749" upper="2.749" effort="18" velocity="36" />
  </joint>
  <link name="left_shoulder_roll_link">
    <inertial>
      <origin xyz="0.000132649636071396 0.00797092570604596 -0.0452123729439791" rpy="0 0 0" />
      <mass value="1.126" />
      <inertia ixx="0.00147895653317204" ixy="-3.2910073590523E-07" ixz="1.87137523621959E-06" iyy="0.0014110761279569" iyz="0.00014229856792806" izz="0.000629153731234365" />
    </inertial>
    <visual>
      <origin xyz="0 0 0" rpy="0 0 0" />
      <geometry>
        <mesh filename="meshes/left_shoulder_roll_link.STL" />
      </geometry>
      <material name="">
        <color rgba="1.43 1.43 1.43 1" />
      </material>
    </visual>
    <collision>
      <origin xyz="0 0 0" rpy="0 0 0" />
      <geometry>
        <mesh filename="meshes/left_shoulder_roll_link.STL" />
      </geometry>
    </collision>
  </link>
  <joint name="left_shoulder_roll_joint" type="revolute">
    <origin xyz="0 0.0588 0" rpy="-0.17453 0 0" />
    <parent link="left_shoulder_pitch_link" />
    <child link="left_shoulder_roll_link" />
    <axis xyz="1 0 0" />
    <limit lower="-0.175" upper="2.653" effort="14" velocity="36" />
  </joint>
  <link name="left_shoulder_yaw_link">
    <inertial>
      <origin xyz="-0.00093704 0 -0.07735342" rpy="0 0 0" />
      <mass value="0.896" />
      <inertia ixx="0.00232863" ixy="0" ixz="-0.00005483" iyy="0.00227734" iyz="-0.00000003" izz="0.00068771" />
    </inertial>
    <visual>
      <origin xyz="0 0 0" rpy="0 0 0" />
      <geometry>
        <mesh filename="meshes/left_shoulder_yaw_link.STL" />
      </geometry>
      <material name="">
        <color rgba="1.43 1.43 1.43 1" />
      </material>
    </visual>
    <collision>
      <origin xyz="0 0 0" rpy="0 0 0" />
      <geometry>
        <mesh filename="meshes/left_shoulder_yaw_link.STL" />
      </geometry>
    </collision>
  </link>
  <joint name="left_shoulder_yaw_joint" type="revolute">
    <origin xyz="0 0.018928 -0.10734" rpy="0.17453 0 0" />
    <parent link="left_shoulder_roll_link" />
    <child link="left_shoulder_yaw_link" />
    <axis xyz="0 0 1" />
    <limit lower="-2.618" upper="2.618" effort="14" velocity="36" />
  </joint>
  <link name="left_elbow_link">
    <inertial>
      <origin xyz="0.09455648 -0.00000142 -0.01096866" rpy="0 0 0" />
      <mass value="0.576" />
      <inertia ixx="0.00037157" ixy="0.00000000" ixz="0.00007430" iyy="0.00166798" iyz="0.00000000" izz="0.00168869" />
    </inertial>
    <visual>
      <origin xyz="0 0 0" rpy="0 0 0" />
      <geometry>
        <mesh filename="meshes/left_elbow_link.STL" />
      </geometry>
      <material name="">
        <color rgba="1.43 1.43 1.43 1" />
      </material>
    </visual>
    <collision>
      <origin xyz="0 0 0" rpy="0 0 0" />
      <geometry>
        <mesh filename="meshes/left_elbow_link.STL" />
      </geometry>
    </collision>
  </link>
  <joint name="left_elbow_joint" type="revolute">
    <origin xyz="0.01 0 -0.151" rpy="0 0 0" />
    <parent link="left_shoulder_yaw_link" />
    <child link="left_elbow_link" />
    <axis xyz="0 1 0" />
    <limit lower="-0.873" upper="1.571" effort="14" velocity="36" />
  </joint>
  <link name="left_wrist_roll_link">
    <inertial>
      <origin xyz="0.0750540150567931 -0.00332325697592686 0.00545988837194125" rpy="0 0 0" />
      <mass value="0.692" />
      <inertia ixx="0.000201713138799491" ixy="3.10486462595001E-05" ixz="-1.08851683373094E-05" iyy="0.000582925516717639" iyz="5.89186596698041E-05" izz="0.000537892729539226" />
    </inertial>
    <visual>
      <origin xyz="0 0 0" rpy="0 0 0" />
      <geometry>
        <mesh filename="meshes/left_wrist_roll_link.STL" />
      </geometry>
      <material name="">
        <color rgba="0.419607843137255 0.419607843137255 0.419607843137255 1" />
      </material>
    </visual>
    <collision>
      <origin xyz="0 0 0" rpy="0 0 0" />
      <geometry>
        <mesh filename="meshes/left_wrist_roll_link.STL" />
      </geometry>
    </collision>
  </link>
  <joint name="left_wrist_roll_joint" type="revolute">
    <origin xyz="0.201 0 -0.01" rpy="-0.17453 0 0" />
    <parent link="left_elbow_link" />
    <child link="left_wrist_roll_link" />
    <axis xyz="1 0 0" />
    <limit lower="-2.662" upper="2.662" effort="2.2" velocity="36" />
  </joint>
  <link name="left_base_link">
    <inertial>
      <origin xyz="-0.0052437813922142 0.00340380255263376 0.0521266765719498" rpy="0 0 0" />
      <mass value="0.238" />
      <inertia ixx="2.10911666669912E-05" ixy="3.86322047662032E-08" ixz="9.36399145709391E-08" iyy="1.44621914759073E-05" iyz="-1.09576502000447E-06" izz="7.99811499549963E-06" />
    </inertial>
    <visual>
      <origin xyz="0 0 0" rpy="0 0 0" />
      <geometry>
        <mesh filename="meshes/left_base_link.STL" />
      </geometry>
      <material name="">
        <color rgba="1 1 1 1" />
      </material>
    </visual>
    <collision>
      <origin xyz="0 0 0" rpy="0 0 0" />
      <geometry>
        <mesh filename="meshes/left_base_link.STL" />
      </geometry>
    </collision>
  </link>
  <joint name="left_base_joint" type="fixed">
    <origin xyz="0.015 0 0" rpy="-1.5708 0 -1.5708" /> 
    <parent link="left_wrist_roll_link" />
    <child link="left_base_link" />
    <axis xyz="1 0 0" />
    <limit lower="-2.662" upper="2.662" effort="2.2" velocity="36" />
  </joint>
  <link name="left_thumb_metacarpal_link">
    <inertial>
      <origin xyz="1.51105893291953E-05 -0.00707242532016975 -0.00420847293427094" rpy="0 0 0" />
      <mass value="0.01" />
      <inertia ixx="1.59239837111329E-07" ixy="-4.69100836631313E-09" ixz="4.92933775261579E-10" iyy="1.60913456568321E-07" iyz="-1.48146725871811E-08" izz="5.13550255314669E-08" />
    </inertial>
    <visual>
      <origin xyz="0 0 0" rpy="0 0 0" />
      <geometry>
        <mesh filename="meshes/left_thumb_metacarpal_link.STL" />
      </geometry>
      <material name="">
        <color rgba="1 1 1 1" />
      </material>
    </visual>
    <collision>
      <origin xyz="0 0 0" rpy="0 0 0" />
      <geometry>
        <mesh filename="meshes/left_thumb_metacarpal_link.STL" />
      </geometry>
    </collision>
  </link>
  <joint name="left_thumb_metacarpal_joint" type="revolute">
     <origin xyz="0.005619 -0.019867 0.027825" rpy="0 0 0.16787" />
    <parent link="left_base_link" />
    <child link="left_thumb_metacarpal_link" />
    <axis xyz="0 0 1" />
    <limit lower="0" upper="1.57" effort="0.5" velocity="2.6175" />
  </joint>
  <link name="left_thumb_proximal_link">
    <inertial>
      <origin xyz="-4.69719500198473E-07 -0.0277015013193164 -0.00202656319478134" rpy="0 0 0" />
      <mass value="0.05" />
      <inertia ixx="2.40451952538979E-06" ixy="-1.31092767621418E-10" ixz="8.32477243895752E-12" iyy="5.12323837647516E-07" iyz="-2.89154745634785E-08" izz="2.56254219597565E-06" />
    </inertial>
    <visual>
      <origin xyz="0 0 0" rpy="0 0 0" />
      <geometry>
        <mesh filename="meshes/left_thumb_proximal_link.STL" />
      </geometry>
      <material name="">
        <color rgba="1 1 1 1" />
      </material>
    </visual>
 <visual>
      <origin xyz="0 0 0" rpy="0 0 0" />
      <geometry>
        <mesh filename="meshes/left_thumb_proximal_visual_link.STL" />
      </geometry>
      <material name="">
        <color rgba="1 1 1 1" />
      </material>
    </visual>
    <collision>
      <origin xyz="0 0 0" rpy="0 0 0" />
      <geometry>
        <mesh filename="meshes/left_thumb_proximal_link.STL" />
      </geometry>
    </collision>
  </link>
  <joint name="left_thumb_proximal_joint" type="revolute">
    <origin xyz="0 -0.014227 0" rpy="-0.17488 0.23736 -0.16787" />
    <parent link="left_thumb_metacarpal_link" />
    <child link="left_thumb_proximal_link" />
    <axis xyz="-1 0 0" />
    <limit lower="0" upper="1.03" effort="1.1" velocity="2.5303" />
  </joint>
  <link name="left_thumb_distal_link">
    <inertial>
      <origin xyz="-5.88258312894663E-09 -0.0117544716247141 1.13324397438934E-05" rpy="0 0 0" />
      <mass value="0.01" />
      <inertia ixx="1.67793545309794E-07" ixy="7.1592784782531E-12" ixz="-6.80095370887263E-12" iyy="1.15362128819332E-07" iyz="1.2517499089377E-08" izz="2.19553178338424E-07" />
    </inertial>
    <visual>
      <origin xyz="0 0 0" rpy="0 0 0" />
      <geometry>
        <mesh filename="meshes/left_thumb_distal_link.STL" />
      </geometry>
      <material name="">
        <color rgba="1 1 1 1" />
      </material>
    </visual>
    <collision>
      <origin xyz="0 0 0" rpy="0 0 0" />
      <geometry>
        <mesh filename="meshes/left_thumb_distal_link.STL" />
      </geometry>
    </collision>
  </link>
  <joint name="left_thumb_distal_joint" type="revolute">
    <origin xyz="0 -0.052 0" rpy="0 0 0" />
    <parent link="left_thumb_proximal_link" />
    <child link="left_thumb_distal_link" />
    <axis xyz="-1 0 0" />
    <limit lower="0" upper="1.03" effort="1.1" velocity="2.5303" />
    <mimic joint="left_thumb_proximal_joint" multiplier="1" offset="0" />
  </joint>
  <link name="left_thumb_tip_link">
    </link>
  <joint name="left_thumb_tip_joint" type="fixed">
    <origin xyz="0 -0.026529 -0.0017734" rpy="0.06675 0 0" />
    <parent link="left_thumb_distal_link" />
    <child link="left_thumb_tip_link" />
    <axis xyz="0 0 0" />
    </joint>
  <link name="left_thumb_touch_link">
    <inertial>
      <origin xyz="-1.1806027010175E-08 0.00152252748962305 -0.00778417824955365" rpy="0 0 0" />
      <mass value="0.002" />
      <inertia ixx="1.67793545299225E-07" ixy="7.5594784738105E-12" ixz="-6.38541374289843E-12" iyy="1.14159537766499E-07" iyz="5.47195888787862E-09" izz="2.20755769355424E-07" />
    </inertial>
    <visual>
      <origin xyz="0 0 0" rpy="0 0 0" />
      <geometry>
        <mesh filename="meshes/left_thumb_touch_link.STL" />
      </geometry>
      <material name="">
        <color rgba="1 1 1 1" />
      </material>
    </visual>
    <collision>
      <origin xyz="0 0 0" rpy="0 0 0" />
      <geometry>
        <mesh filename="meshes/left_thumb_touch_link.STL" />
      </geometry>
    </collision>
  </link>
  <joint name="left_thumb_touch_joint" type="fixed">
    <origin xyz="0 -0.013836 0.0076686" rpy="0.17488 0 0" />
    <parent link="left_thumb_distal_link" />
    <child link="left_thumb_touch_link" />
    <axis xyz="0 0 0" />
  </joint>
  <link name="left_index_proximal_link">
    <inertial>
      <origin xyz="-0.00223495193199565 -3.15874577787312E-06 0.0176402020341366" rpy="0 0 0" />
      <mass value="0.009" />
      <inertia ixx="2.51945688372283E-07" ixy="1.19772964297278E-11" ixz="-6.37275644668917E-09" iyy="2.36435336139899E-07" iyz="1.65019165740599E-10" izz="9.30351046594029E-08" />
    </inertial>
    <visual>
      <origin xyz="0 0 0" rpy="0 0 0" />
      <geometry>
        <mesh filename="meshes/left_index_proximal_link.STL" />
      </geometry>
      <material name="">
        <color rgba="1 1 1 1" />
      </material>
    </visual>
    <collision>
      <origin xyz="0 0 0" rpy="0 0 0" />
      <geometry>
        <mesh filename="meshes/left_index_proximal_link.STL" />
      </geometry>
    </collision>
  </link>
  <joint name="left_index_proximal_joint" type="revolute">
    <origin xyz="-0.0021349 -0.029578 0.080876" rpy="0.11819 0.14743 0.17422" />
    <parent link="left_base_link" />
    <child link="left_index_proximal_link" />
    <axis xyz="0 1 0" />
    <limit lower="0" upper="1.41" effort="2" velocity="2.2685" />
  </joint>
  <link name="left_index_distal_link">
    <inertial>
      <origin xyz="0.00330169965345207 -1.80502678033545E-07 0.0142076903844267" rpy="0 0 0" />
      <mass value="0.009" />
      <inertia ixx="3.39968050760851E-07" ixy="-2.72439842925177E-12" ixz="-8.75041192697868E-08" iyy="3.62244794159632E-07" iyz="-3.69168934117452E-12" izz="9.1034511229316E-08" />
    </inertial>
    <visual>
      <origin xyz="0 0 0" rpy="0 0 0" />
      <geometry>
        <mesh filename="meshes/left_index_distal_link.STL" />
      </geometry>
      <material name="">
        <color rgba="1 1 1 1" />
      </material>
    </visual>
    <collision>
      <origin xyz="0 0 0" rpy="0 0 0" />
      <geometry>
        <mesh filename="meshes/left_index_distal_link.STL" />
      </geometry>
    </collision>
  </link>
  <joint name="left_index_distal_joint" type="revolute">
    <origin xyz="0 0 0.032" rpy="0 0 0" />
    <parent link="left_index_proximal_link" />
    <child link="left_index_distal_link" />
    <axis xyz="0 1 0" />
    <limit lower="0" upper="1.63" effort="2" velocity="2.2685" />
    <mimic joint="left_index_proximal_joint" multiplier="1.155" offset="0" />
  </joint>
  <link name="left_index_tip_link">
    </link>
  <joint name="left_index_tip_joint" type="fixed">
    <origin xyz="0.011097 0 0.035739" rpy="0 0.4756 0" />
    <parent link="left_index_distal_link" />
    <child link="left_index_tip_link" />
    <axis xyz="0 0 0" />
    </joint>
  <link name="left_index_touch_link">
    <inertial>
      <origin xyz="-0.00299911641156304 -0.00249742609184543 -0.000361457745670764" rpy="0 0 0" />
      <mass value="0.002" />
      <inertia ixx="6.77691690725075E-09" ixy="1.49925053858217E-09" ixz="-2.16894115716066E-10" iyy="3.23801290825914E-09" iyz="3.14646833837905E-10" izz="5.36791538949697E-09" />
    </inertial>
    <visual>
      <origin xyz="0 0 0" rpy="0 0 0" />
      <geometry>
        <mesh filename="meshes/left_index_touch_link.STL" />
      </geometry>
      <material name="">
        <color rgba="1 1 1 1" />
      </material>
    </visual>
    <collision>
      <origin xyz="0 0 0" rpy="0 0 0" />
      <geometry>
        <mesh filename="meshes/left_index_touch_link.STL" />
      </geometry>
    </collision>
  </link>
  <joint name="left_index_touch_joint" type="fixed">
    <origin xyz="0.014497 0 0.023303" rpy="0 0.4756 0" />
    <parent link="left_index_distal_link" />
    <child link="left_index_touch_link" />
    <axis xyz="0 0 0" />
  </joint>
  <link name="left_middle_proximal_link">
    <inertial>
      <origin xyz="-0.00222511101223747 -5.25632286623237E-06 0.0203007776295123" rpy="0 0 0" />
      <mass value="0.009" />
      <inertia ixx="3.6699623719538E-07" ixy="2.68340899395639E-11" ixz="-9.79836587937102E-09" iyy="3.52645347928613E-07" iyz="2.5786558273981E-10" izz="1.12233932527467E-07" />
    </inertial>
    <visual>
      <origin xyz="0 0 0" rpy="0 0 0" />
      <geometry>
        <mesh filename="meshes/left_middle_proximal_link.STL" />
      </geometry>
      <material name="">
        <color rgba="1 1 1 1" />
      </material>
    </visual>
    <collision>
      <origin xyz="0 0 0" rpy="0 0 0" />
      <geometry>
        <mesh filename="meshes/left_middle_proximal_link.STL" />
      </geometry>
    </collision>
  </link>
  <joint name="left_middle_proximal_joint" type="revolute">
    <origin xyz="-0.0045767 -0.010051 0.084993" rpy="0.039468 0.1483 0.057975" />
    <parent link="left_base_link" />
    <child link="left_middle_proximal_link" />
    <axis xyz="0 1 0" />
    <limit lower="0" upper="1.41" effort="2" velocity="2.2685" />
  </joint>
  <link name="left_middle_distal_link">
    <inertial>
      <origin xyz="0.00400815246049972 2.93852058033672E-08 0.0164973984498919" rpy="0 0 0" />
      <mass value="0.009" />
      <inertia ixx="5.12550471641205E-07" ixy="2.4957446124327E-12" ixz="-1.36569370373267E-07" iyy="5.4982769389762E-07" iyz="1.1510593712868E-12" izz="1.23560211132881E-07" />
    </inertial>
    <visual>
      <origin xyz="0 0 0" rpy="0 0 0" />
      <geometry>
        <mesh filename="meshes/left_middle_distal_link.STL" />
      </geometry>
      <material name="">
        <color rgba="1 1 1 1" />
      </material>
    </visual>
    <collision>
      <origin xyz="0 0 0" rpy="0 0 0" />
      <geometry>
        <mesh filename="meshes/left_middle_distal_link.STL" />
      </geometry>
    </collision>
  </link>
  <joint name="left_middle_distal_joint" type="revolute">
    <origin xyz="0 0 0.037" rpy="0 0.12654 0" />
    <parent link="left_middle_proximal_link" />
    <child link="left_middle_distal_link" />
    <axis xyz="0 1 0" />
    <limit lower="0" upper="1.63" effort="2" velocity="2.2685" />
    <mimic joint="left_middle_proximal_joint" multiplier="1.155" offset="0" />
  </joint>
  <link name="left_middle_tip_link">
    </link>
  <joint name="left_middle_tip_joint" type="fixed">
    <origin xyz="0.0073534 0 0.041703" rpy="0 0.34907 0" />
    <parent link="left_middle_distal_link" />
    <child link="left_middle_tip_link" />
    <axis xyz="0 0 0" />
    </joint>
  <link name="left_middle_touch_link">
    <inertial>
      <origin xyz="-0.00319289171453651 1.92251098651841E-08 0.00297860354010647" rpy="0 0 0" />
      <mass value="0.002" />
      <inertia ixx="1.00486658585813E-08" ixy="-7.87051809312931E-14" ixz="2.25917784171234E-09" iyy="8.23228109049258E-09" iyz="1.50825328552765E-13" izz="4.41272192206512E-09" />
    </inertial>
    <visual>
      <origin xyz="0 0 0" rpy="0 0 0" />
      <geometry>
        <mesh filename="meshes/left_middle_touch_link.STL" />
      </geometry>
      <material name="">
        <color rgba="1 1 1 1" />
      </material>
    </visual>
    <collision>
      <origin xyz="0 0 0" rpy="0 0 0" />
      <geometry>
        <mesh filename="meshes/left_middle_touch_link.STL" />
      </geometry>
    </collision>
  </link>
  <joint name="left_middle_touch_joint" type="fixed">
    <origin xyz="0.012493 0 0.028393" rpy="0 0.34907 0" />
    <parent link="left_middle_distal_link" />
    <child link="left_middle_touch_link" />
    <axis xyz="0 0 0" />
  </joint>
  <link name="left_ring_proximal_link">
    <inertial>
      <origin xyz="-0.00234494526421452 -5.87954755621161E-06 0.019177402549597" rpy="0 0 0" />
      <mass value="0.009" />
      <inertia ixx="3.14177684848335E-07" ixy="3.34382331089976E-11" ixz="-7.78981780892183E-09" iyy="2.97613170150896E-07" iyz="2.41251871804457E-10" izz="1.0211543233675E-07" />
    </inertial>
    <visual>
      <origin xyz="0 0 0" rpy="0 0 0" />
      <geometry>
        <mesh filename="meshes/left_ring_proximal_link.STL" />
      </geometry>
      <material name="">
        <color rgba="1 1 1 1" />
      </material>
    </visual>
    <collision>
      <origin xyz="0 0 0" rpy="0 0 0" />
      <geometry>
        <mesh filename="meshes/left_ring_proximal_link.STL" />
      </geometry>
    </collision>
  </link>
  <joint name="left_ring_proximal_joint" type="revolute">
    <origin xyz="-0.0046877 0.010026 0.083982" rpy="-0.039462 0.14721 -0.057932" />
    <parent link="left_base_link" />
    <child link="left_ring_proximal_link" />
    <axis xyz="0 1 0" />
    <limit lower="0" upper="1.41" effort="2" velocity="2.2685" />
  </joint>
  <link name="left_ring_distal_link">
    <inertial>
      <origin xyz="0.00382459959210406 -7.8017874437751E-08 0.0160343764410312" rpy="0 0 0" />
      <mass value="0.009" />
      <inertia ixx="4.71792497420504E-07" ixy="-6.95225674723301E-13" ixz="-1.26948440940938E-07" iyy="5.06071998616974E-07" iyz="-2.19413968646526E-12" izz="1.15762768100302E-07" />
    </inertial>
    <visual>
      <origin xyz="0 0 0" rpy="0 0 0" />
      <geometry>
        <mesh filename="meshes/left_ring_distal_link.STL" />
      </geometry>
      <material name="">
        <color rgba="1 1 1 1" />
      </material>
    </visual>
    <collision>
      <origin xyz="0 0 0" rpy="0 0 0" />
      <geometry>
        <mesh filename="meshes/left_ring_distal_link.STL" />
      </geometry>
    </collision>
  </link>
  <joint name="left_ring_distal_joint" type="revolute">
    <origin xyz="0 0 0.035" rpy="0 0.12654 0" />
    <parent link="left_ring_proximal_link" />
    <child link="left_ring_distal_link" />
    <axis xyz="0 1 0" />
    <limit lower="0" upper="1.63" effort="2" velocity="2.2685" />
    <mimic joint="left_ring_proximal_joint" multiplier="1.155" offset="0" />
  </joint>
  <link name="left_ring_tip_link">
    </link>
  <joint name="left_ring_tip_joint" type="fixed">
    <origin xyz="0.0071824 0 0.040734" rpy="0 0.34907 0" />
    <parent link="left_ring_distal_link" />
    <child link="left_ring_tip_link" />
    <axis xyz="0 0 0" />
    </joint>
  <link name="left_ring_touch_link">
    <inertial>
      <origin xyz="-0.00302345770059939 4.42584829375703E-08 0.0030407600788087" rpy="0 0 0" />
      <mass value="0.002" />
      <inertia ixx="8.20180993934663E-09" ixy="-2.63295949836146E-14" ixz="1.83211342144402E-09" iyy="6.63652036961065E-09" iyz="1.12534283673606E-13" izz="3.61925974724395E-09" />
    </inertial>
    <visual>
      <origin xyz="0 0 0" rpy="0 0 0" />
      <geometry>
        <mesh filename="meshes/left_ring_touch_link.STL" />
      </geometry>
      <material name="">
        <color rgba="1 1 1 1" />
      </material>
    </visual>
    <collision>
      <origin xyz="0 0 0" rpy="0 0 0" />
      <geometry>
        <mesh filename="meshes/left_ring_touch_link.STL" />
      </geometry>
    </collision>
  </link>
  <joint name="left_ring_touch_joint" type="fixed">
    <origin xyz="0.012028 0 0.027796" rpy="0 0.34907 0" />
    <parent link="left_ring_distal_link" />
    <child link="left_ring_touch_link" />
    <axis xyz="0 0 0" />
  </joint>
  <link name="left_pinky_proximal_link">
    <inertial>
      <origin xyz="-0.00213212021184178 -7.75039446098032E-06 0.0160671583560383" rpy="0 0 0" />
      <mass value="0.009" />
      <inertia ixx="1.97563213550085E-07" ixy="2.23402433057963E-11" ixz="-4.58425663692079E-09" iyy="1.82023043083307E-07" iyz="1.08028441152494E-10" izz="8.21624712033168E-08" />
    </inertial>
    <visual>
      <origin xyz="0 0 0" rpy="0 0 0" />
      <geometry>
        <mesh filename="meshes/left_pinky_proximal_link.STL" />
      </geometry>
      <material name="">
        <color rgba="1 1 1 1" />
      </material>
    </visual>
    <collision>
      <origin xyz="0 0 0" rpy="0 0 0" />
      <geometry>
        <mesh filename="meshes/left_pinky_proximal_link.STL" />
      </geometry>
    </collision>
  </link>
  <joint name="left_pinky_proximal_joint" type="revolute">
    <origin xyz="-0.0023566 0.029366 0.078694" rpy="-0.11815 0.14491 -0.17392" />
    <parent link="left_base_link" />
    <child link="left_pinky_proximal_link" />
    <axis xyz="0 1 0" />
    <limit lower="0" upper="1.41" effort="2" velocity="2.2685" />
  </joint>
  <link name="left_pinky_distal_link">
    <inertial>
      <origin xyz="0.00307974197235919 1.54572112227858E-07 0.0130246967256256" rpy="0 0 0" />
      <mass value="0.009" />
      <inertia ixx="2.70050429038431E-07" ixy="1.68029751000565E-12" ixz="-6.70780254430148E-08" iyy="2.85275081521347E-07" iyz="5.10635117768255E-12" izz="7.90798706854226E-08" />
    </inertial>
    <visual>
      <origin xyz="0 0 0" rpy="0 0 0" />
      <geometry>
        <mesh filename="meshes/left_pinky_distal_link.STL" />
      </geometry>
      <material name="">
        <color rgba="1 1 1 1" />
      </material>
    </visual>
    <collision>
      <origin xyz="0 0 0" rpy="0 0 0" />
      <geometry>
        <mesh filename="meshes/left_pinky_distal_link.STL" />
      </geometry>
    </collision>
  </link>
  <joint name="left_pinky_distal_joint" type="revolute">
    <origin xyz="0 0 0.029" rpy="0 0 0" />
    <parent link="left_pinky_proximal_link" />
    <child link="left_pinky_distal_link" />
    <axis xyz="0 1 0" />
    <limit lower="0" upper="1.63" effort="2" velocity="2.2685" />
    <mimic joint="left_pinky_proximal_joint" multiplier="1.155" offset="0" />
  </joint>
  <link name="left_pinky_tip_link">
    </link>
  <joint name="left_pinky_tip_joint" type="fixed">
    <origin xyz="0.010221 0 0.032918" rpy="0 0.4756 0" />
    <parent link="left_pinky_distal_link" />
    <child link="left_pinky_tip_link" />
    <axis xyz="0 0 0" />
    </joint>
  <link name="left_pinky_touch_link">
    <inertial>
      <origin xyz="-0.00289142401155668 2.00563398826403E-07 0.00165387959177493" rpy="0 0 0" />
      <mass value="0.002" />
      <inertia ixx="6.91911795672566E-09" ixy="1.21758056374209E-13" ixz="1.42748611971717E-09" iyy="5.34364749688619E-09" iyz="7.16346527443829E-14" izz="3.28289727389894E-09" />
    </inertial>
    <visual>
      <origin xyz="0 0 0" rpy="0 0 0" />
      <geometry>
        <mesh filename="meshes/left_pinky_touch_link.STL" />
      </geometry>
      <material name="">
        <color rgba="1 1 1 1" />
      </material>
    </visual>
    <collision>
      <origin xyz="0 0 0" rpy="0 0 0" />
      <geometry>
        <mesh filename="meshes/left_pinky_touch_link.STL" />
      </geometry>
    </collision>
  </link>
  <joint name="left_pinky_touch_joint" type="fixed">
    <origin xyz="0.01401 0 0.021124" rpy="0 0.4756 0" />
    <parent link="left_pinky_distal_link" />
    <child link="left_pinky_touch_link" />
    <axis xyz="0 0 0" />
  </joint>
  <link name="right_shoulder_pitch_link">
    <inertial>
      <origin xyz="0 -0.02913268 0" rpy="0 0 0" />
      <mass value="0.276" />
      <inertia ixx="0.00019627" ixy="0" ixz="0" iyy="0.00021249" iyz="0" izz="0.00033854" />
    </inertial>
    <visual>
      <origin xyz="0 0 0" rpy="0 0 0" />
      <geometry>
        <mesh filename="meshes/right_shoulder_pitch_link.STL" />
      </geometry>
      <material name="">
        <color rgba="0.419607843137255 0.419607843137255 0.419607843137255 1" />
      </material>
    </visual>
    <!-- <collision>
      <origin xyz="0 0 0" rpy="0 0 0" />
      <geometry>
        <mesh filename="meshes/right_shoulder_pitch_link.STL" />
      </geometry>
    </collision> -->
  </link>
  <joint name="right_shoulder_pitch_joint" type="revolute">
    <origin xyz="-0.01 -0.13365 0.31135" rpy="-0.17453 0 0" />
    <parent link="torso_link" />
    <child link="right_shoulder_pitch_link" />
    <axis xyz="0 1 0" />
    <limit lower="-2.749" upper="2.749" effort="18" velocity="36" />
  </joint>
  <link name="right_shoulder_roll_link">
    <inertial>
      <origin xyz="0.000132993704568058 -0.00797311460563502 -0.0452117001578095" rpy="0 0 0" />
      <mass value="1.126" />
      <inertia ixx="0.00147895611802897" ixy="3.31494377717319E-07" ixz="1.87169668439229E-06" iyy="0.00141107336129469" iyz="-0.000142297630828012" izz="0.000629151068523018" />
    </inertial>
    <visual>
      <origin xyz="0 0 0" rpy="0 0 0" />
      <geometry>
        <mesh filename="meshes/right_shoulder_roll_link.STL" />
      </geometry>
      <material name="">
        <color rgba="1.43 1.43 1.43 1" />
      </material>
    </visual>
    <collision>
      <origin xyz="0 0 0" rpy="0 0 0" />
      <geometry>
        <mesh filename="meshes/right_shoulder_roll_link.STL" />
      </geometry>
    </collision>
  </link>
  <joint name="right_shoulder_roll_joint" type="revolute">
    <origin xyz="0 -0.0588 0" rpy="0.17453 0 0" />
    <parent link="right_shoulder_pitch_link" />
    <child link="right_shoulder_roll_link" />
    <axis xyz="1 0 0" />
    <limit lower="-2.653" upper="0.175" effort="14" velocity="36" />
  </joint>
  <link name="right_shoulder_yaw_link">
    <inertial>
      <origin xyz="-0.0009376 0 -0.07735381" rpy="0 0 0" />
      <mass value="0.896" />
      <inertia ixx="0.00232864" ixy="-0.00000001" ixz="-0.00005482" iyy="0.00227735" iyz="0.00000002" izz="0.00068771" />
    </inertial>
    <visual>
      <origin xyz="0 0 0" rpy="0 0 0" />
      <geometry>
        <mesh filename="meshes/right_shoulder_yaw_link.STL" />
      </geometry>
      <material name="">
        <color rgba="1.43 1.43 1.43 1" />
      </material>
    </visual>
    <collision>
      <origin xyz="0 0 0" rpy="0 0 0" />
      <geometry>
        <mesh filename="meshes/right_shoulder_yaw_link.STL" />
      </geometry>
    </collision>
  </link>
  <joint name="right_shoulder_yaw_joint" type="revolute">
    <origin xyz="0 -0.018928 -0.10734" rpy="-0.17453 0 0" />
    <parent link="right_shoulder_roll_link" />
    <child link="right_shoulder_yaw_link" />
    <axis xyz="0 0 1" />
    <limit lower="-2.618" upper="2.618" effort="14" velocity="36" />
  </joint>
  <link name="right_elbow_link">
    <inertial>
      <origin xyz="0.09455648 -0.00000142 -0.01096866" rpy="0 0 0" />
      <mass value="0.576" />
      <inertia ixx="0.00037157" ixy="0.00000000" ixz="0.00007430" iyy="0.00166798" iyz="0.00000000" izz="0.00168869" />
    </inertial>
    <visual>
      <origin xyz="0 0 0" rpy="0 0 0" />
      <geometry>
        <mesh filename="meshes/right_elbow_link.STL" />
      </geometry>
      <material name="">
        <color rgba="1.43 1.43 1.43 1" />
      </material>
    </visual>
    <collision>
      <origin xyz="0 0 0" rpy="0 0 0" />
      <geometry>
        <mesh filename="meshes/right_elbow_link.STL" />
      </geometry>
    </collision>
  </link>
  <joint name="right_elbow_joint" type="revolute">
    <origin xyz="0.01 0 -0.151" rpy="0 0 0" />
    <parent link="right_shoulder_yaw_link" />
    <child link="right_elbow_link" />
    <axis xyz="0 1 0" />
    <limit lower="-0.873" upper="1.571" effort="14" velocity="36" />
  </joint>
  <link name="right_wrist_roll_link">
    <inertial>
      <origin xyz="0.0750546041268602 0.00332420954903981 0.0054573869223207" rpy="0 0 0" />
      <mass value="0.692" />
      <inertia ixx="0.00020172769789739" ixy="-3.10498593261659E-05" ixz="-1.08851122263175E-05" iyy="0.000582928121150921" iyz="-5.89257229189113E-05" izz="0.000537898939865876" />
    </inertial>
    <visual>
      <origin xyz="0 0 0" rpy="0 0 0" />
      <geometry>
        <mesh filename="meshes/right_wrist_roll_link.STL" />
      </geometry>
      <material name="">
        <color rgba="0.419607843137255 0.419607843137255 0.419607843137255 1" />
      </material>
    </visual>
    <collision>
      <origin xyz="0 0 0" rpy="0 0 0" />
      <geometry>
        <mesh filename="meshes/right_wrist_roll_link.STL" />
      </geometry>
    </collision>
  </link>
  <joint name="right_wrist_roll_joint" type="revolute">
    <origin xyz="0.201 0 -0.01" rpy="0.17453 0 0" />
    <parent link="right_elbow_link" />
    <child link="right_wrist_roll_link" />
    <axis xyz="1 0 0" />
    <limit lower="-2.662" upper="2.662" effort="2.2" velocity="36" />
  </joint>
  <link name="right_base_link">
    <inertial>
      <origin xyz="-0.0052437813922142 -0.00340380255263376 0.0521266765719498" rpy="0 0 0" />
      <mass value="0.238" />
      <inertia ixx="2.10911666669912E-05" ixy="3.86322047662032E-08" ixz="9.36399145709391E-08" iyy="1.44621914759073E-05" iyz="-1.09576502000447E-06" izz="7.99811499549963E-06" />
    </inertial>
    <visual>
      <origin xyz="0 0 0" rpy="0 0 0" />
      <geometry>
        <mesh filename="meshes/right_base_link.STL" />
      </geometry>
      <material name="">
        <color rgba="1 1 1 1" />
      </material>
    </visual>
    <collision>
      <origin xyz="0 0 0" rpy="0 0 0" />
      <geometry>
        <mesh filename="meshes/right_base_link.STL" />
      </geometry>
    </collision>
  </link>
  <joint name="right_base_joint" type="fixed">
    <origin xyz="0.015 0 0" rpy="1.5708 0 1.5708" />
    <parent link="right_wrist_roll_link" />
    <child link="right_base_link" />
    <axis xyz="1 0 0" />
    <limit lower="-2.662" upper="2.662" effort="2.2" velocity="36" />
  </joint>
  <link name="right_thumb_metacarpal_link">
    <inertial>
      <origin xyz="1.51105893291953E-05 0.00707242532016975 -0.00420847293427094" rpy="0 0 0" />
      <mass value="0.01" />
      <inertia ixx="1.59239837111329E-07" ixy="-4.69100836631313E-09" ixz="4.92933775261579E-10" iyy="1.60913456568321E-07" iyz="-1.48146725871811E-08" izz="5.13550255314669E-08" />
    </inertial>
    <visual>
      <origin xyz="0 0 0" rpy="0 0 0" />
      <geometry>
        <mesh filename="meshes/right_thumb_metacarpal_link.STL" />
      </geometry>
      <material name="">
        <color rgba="1 1 1 1" />
      </material>
    </visual>
    <collision>
      <origin xyz="0 0 0" rpy="0 0 0" />
      <geometry>
        <mesh filename="meshes/right_thumb_metacarpal_link.STL" />
      </geometry>
    </collision>
  </link>
  <joint name="right_thumb_metacarpal_joint" type="revolute">
    <origin xyz="0.005619 0.019867 0.027825" rpy="0 0 -0.16787" />
    <parent link="right_base_link" />
    <child link="right_thumb_metacarpal_link" />
    <axis xyz="0 0 -1" />
    <limit lower="0" upper="1.57" effort="0.5" velocity="2.6175" />
  </joint>
  <link name="right_thumb_proximal_link">
    <inertial>
      <origin xyz="-4.69719500198473E-07 0.0277015013193164 -0.00202656319478134" rpy="0 0 0" />
      <mass value="0.05" />
      <inertia ixx="2.40451952538979E-06" ixy="-1.31092767621418E-10" ixz="8.32477243895752E-12" iyy="5.12323837647516E-07" iyz="-2.89154745634785E-08" izz="2.56254219597565E-06" />
    </inertial>
    <visual>
      <origin xyz="0 0 0" rpy="0 0 0" />
      <geometry>
        <mesh filename="meshes/right_thumb_proximal_visual_link.STL" />
      </geometry>
      <material name="">
        <color rgba="1 1 1 1" />
      </material>
    </visual>
    <collision>
      <origin xyz="0 0 0" rpy="0 0 0" />
      <geometry>
        <mesh filename="meshes/right_thumb_proximal_link.STL" />
      </geometry>
    </collision>
  </link>
  <joint name="right_thumb_proximal_joint" type="revolute">
    <origin xyz="0 0.014227 0" rpy="0.17488 0.23736 0.16787" />
    <parent link="right_thumb_metacarpal_link" />
    <child link="right_thumb_proximal_link" />
    <axis xyz="1 0 0" />
    <limit lower="0" upper="1.03" effort="1.1" velocity="2.5303" />
  </joint>
  <link name="right_thumb_distal_link">
    <inertial>
      <origin xyz="-5.88258312894663E-09 0.0117544716247141 1.13324397438934E-05" rpy="0 0 0" />
      <mass value="0.01" />
      <inertia ixx="1.67793545309794E-07" ixy="7.1592784782531E-12" ixz="-6.80095370887263E-12" iyy="1.15362128819332E-07" iyz="1.2517499089377E-08" izz="2.19553178338424E-07" />
    </inertial>
    <visual>
      <origin xyz="0 0 0" rpy="0 0 0" />
      <geometry>
        <mesh filename="meshes/right_thumb_distal_link.STL" />
      </geometry>
      <material name="">
        <color rgba="1 1 1 1" />
      </material>
    </visual>
    <collision>
      <origin xyz="0 0 0" rpy="0 0 0" />
      <geometry>
        <mesh filename="meshes/right_thumb_distal_link.STL" />
      </geometry>
    </collision>
  </link>
  <joint name="right_thumb_distal_joint" type="revolute">
    <origin xyz="0 0.052 0" rpy="0 0 0" />
    <parent link="right_thumb_proximal_link" />
    <child link="right_thumb_distal_link" />
    <axis xyz="1 0 0" />
    <limit lower="0" upper="1.03" effort="1.1" velocity="2.5303" />
    <mimic joint="right_thumb_proximal_joint" multiplier="1" offset="0" />
  </joint>
  <link name="right_thumb_tip_link">
    </link>
  <joint name="right_thumb_tip_joint" type="fixed">
    <origin xyz="0 0.0265287811635831 -0.00177344281307929" rpy="-0.0667504507189062 0 0" />
    <parent link="right_thumb_distal_link" />
    <child link="right_thumb_tip_link" />
    <axis xyz="0 0 0" />
    </joint>
  <link name="right_thumb_touch_link">
    <inertial>
      <origin xyz="-1.1806027010175E-08 -0.00152252748962305 -0.00778417824955365" rpy="0 0 0" />
      <mass value="0.002" />
      <inertia ixx="1.67793545299225E-07" ixy="7.5594784738105E-12" ixz="-6.38541374289843E-12" iyy="1.14159537766499E-07" iyz="5.47195888787862E-09" izz="2.20755769355424E-07" />
    </inertial>
    <visual>
      <origin xyz="0 0 0" rpy="0 0 0" />
      <geometry>
        <mesh filename="meshes/right_thumb_touch_link.STL" />
      </geometry>
      <material name="">
        <color rgba="1 1 1 1" />
      </material>
    </visual>
    <collision>
      <origin xyz="0 0 0" rpy="0 0 0" />
      <geometry>
        <mesh filename="meshes/right_thumb_touch_link.STL" />
      </geometry>
    </collision>
  </link>
  <joint name="right_thumb_touch_joint" type="fixed">
     <origin xyz="0 0.013836 0.0076686" rpy="-0.17488 0 0" />
    <parent link="right_thumb_distal_link" />
    <child link="right_thumb_touch_link" />
    <axis xyz="0 0 0" />
  </joint>
  <link name="right_index_proximal_link">
    <inertial>
      <origin xyz="-0.00223495193199565 3.15874577787312E-06 0.0176402020341366" rpy="0 0 0" />
      <mass value="0.009" />
      <inertia ixx="2.51945688372283E-07" ixy="1.19772964297278E-11" ixz="-6.37275644668917E-09" iyy="2.36435336139899E-07" iyz="1.65019165740599E-10" izz="9.30351046594029E-08" />
    </inertial>
    <visual>
      <origin xyz="0 0 0" rpy="0 0 0" />
      <geometry>
        <mesh filename="meshes/right_index_proximal_link.STL" />
      </geometry>
      <material name="">
        <color rgba="1 1 1 1" />
      </material>
    </visual>
    <collision>
      <origin xyz="0 0 0" rpy="0 0 0" />
      <geometry>
        <mesh filename="meshes/right_index_proximal_link.STL" />
      </geometry>
    </collision>
  </link>
  <joint name="right_index_proximal_joint" type="revolute">
    <origin xyz="-0.0021349 0.029578 0.080876" rpy="-0.11819 0.14743 -0.17422" />
    <parent link="right_base_link" />
    <child link="right_index_proximal_link" />
    <axis xyz="0 1 0" />
    <limit lower="0" upper="1.41" effort="2" velocity="2.2685" />
  </joint>
  <link name="right_index_distal_link">
    <inertial>
      <origin xyz="0.00330169965345207 1.80502678033545E-07 0.0142076903844267" rpy="0 0 0" />
      <mass value="0.009" />
      <inertia ixx="3.39968050760851E-07" ixy="-2.72439842925177E-12" ixz="-8.75041192697868E-08" iyy="3.62244794159632E-07" iyz="-3.69168934117452E-12" izz="9.1034511229316E-08" />
    </inertial>
    <visual>
      <origin xyz="0 0 0" rpy="0 0 0" />
      <geometry>
        <mesh filename="meshes/right_index_distal_link.STL" />
      </geometry>
      <material name="">
        <color rgba="1 1 1 1" />
      </material>
    </visual>
    <collision>
      <origin xyz="0 0 0" rpy="0 0 0" />
      <geometry>
        <mesh filename="meshes/right_index_distal_link.STL" />
      </geometry>
    </collision>
  </link>
  <joint name="right_index_distal_joint" type="revolute">
    <origin xyz="0 0 0.032" rpy="0 0 0" />
    <parent link="right_index_proximal_link" />
    <child link="right_index_distal_link" />
    <axis xyz="0 1 0" />
    <limit lower="0" upper="1.63" effort="2" velocity="2.2685" />
    <mimic joint="right_index_proximal_joint" multiplier="1.155" offset="0" />
  </joint>
  <link name="right_index_tip_link">
    </link>
  <joint name="right_index_tip_joint" type="fixed">
    <origin xyz="0.011097 0 0.035739" rpy="0 0.4756 0" />
    <parent link="right_index_distal_link" />
    <child link="right_index_tip_link" />
    <axis xyz="0 0 0" />
    </joint>
  <link name="right_index_touch_link">
    <inertial>
      <origin xyz="-0.00299911641156304 0.00249742609184543 -0.000361457745670764" rpy="0 0 0" />
      <mass value="0.002" />
      <inertia ixx="6.77691690725075E-09" ixy="1.49925053858217E-09" ixz="-2.16894115716066E-10" iyy="3.23801290825914E-09" iyz="3.14646833837905E-10" izz="5.36791538949697E-09" />
    </inertial>
    <visual>
      <origin xyz="0 0 0" rpy="0 0 0" />
      <geometry>
        <mesh filename="meshes/right_index_touch_link.STL" />
      </geometry>
      <material name="">
        <color rgba="1 1 1 1" />
      </material>
    </visual>
    <collision>
      <origin xyz="0 0 0" rpy="0 0 0" />
      <geometry>
        <mesh filename="meshes/right_index_touch_link.STL" />
      </geometry>
    </collision>
  </link>
  <joint name="right_index_touch_joint" type="fixed">
    <origin xyz="0.014497 0 0.023303" rpy="1.7145 0.4756 0" />
    <parent link="right_index_distal_link" />
    <child link="right_index_touch_link" />
    <axis xyz="0 0 0" />
  </joint>
  <link name="right_middle_proximal_link">
    <inertial>
      <origin xyz="-0.00222511101223747 5.25632286623237E-06 0.0203007776295123" rpy="0 0 0" />
      <mass value="0.009" />
      <inertia ixx="3.6699623719538E-07" ixy="2.68340899395639E-11" ixz="-9.79836587937102E-09" iyy="3.52645347928613E-07" iyz="2.5786558273981E-10" izz="1.12233932527467E-07" />
    </inertial>
    <visual>
      <origin xyz="0 0 0" rpy="0 0 0" />
      <geometry>
        <mesh filename="meshes/right_middle_proximal_link.STL" />
      </geometry>
      <material name="">
        <color rgba="1 1 1 1" />
      </material>
    </visual>
    <collision>
      <origin xyz="0 0 0" rpy="0 0 0" />
      <geometry>
        <mesh filename="meshes/right_middle_proximal_link.STL" />
      </geometry>
    </collision>
  </link>
  <joint name="right_middle_proximal_joint" type="revolute">
    <origin xyz="-0.0045767 0.010051 0.084993" rpy="-0.039468 0.1483 -0.057975" />
    <parent link="right_base_link" />
    <child link="right_middle_proximal_link" />
    <axis xyz="0 1 0" />
    <limit lower="0" upper="1.41" effort="2" velocity="2.2685" />
  </joint>
  <link name="right_middle_distal_link">
    <inertial>
      <origin xyz="0.00400815246049972 -2.93852058033672E-08 0.0164973984498919" rpy="0 0 0" />
      <mass value="0.009" />
      <inertia ixx="5.12550471641205E-07" ixy="2.4957446124327E-12" ixz="-1.36569370373267E-07" iyy="5.4982769389762E-07" iyz="1.1510593712868E-12" izz="1.23560211132881E-07" />
    </inertial>
    <visual>
      <origin xyz="0 0 0" rpy="0 0 0" />
      <geometry>
        <mesh filename="meshes/right_middle_distal_link.STL" />
      </geometry>
      <material name="">
        <color rgba="1 1 1 1" />
      </material>
    </visual>
    <collision>
      <origin xyz="0 0 0" rpy="0 0 0" />
      <geometry>
        <mesh filename="meshes/right_middle_distal_link.STL" />
      </geometry>
    </collision>
  </link>
  <joint name="right_middle_distal_joint" type="revolute">
    <origin xyz="0 0 0.037" rpy="0 0 0" />
    <parent link="right_middle_proximal_link" />
    <child link="right_middle_distal_link" />
    <axis xyz="0 1 0" />
    <limit lower="0" upper="1.63" effort="2" velocity="2.2685" />
    <mimic joint="right_middle_proximal_joint" multiplier="1.155" offset="0" />
  </joint>
  <link name="right_middle_tip_link">
    </link>
  <joint name="right_middle_tip_joint" type="fixed">
    <origin xyz="0.012558 0 0.040442" rpy="0 0.4756 0" />
    <parent link="right_middle_distal_link" />
    <child link="right_middle_tip_link" />
    <axis xyz="0 0 0" />
    </joint>
  <link name="right_middle_touch_link">
    <inertial>
      <origin xyz="-0.00319289171453651 -1.92251098651841E-08 0.00297860354010647" rpy="0 0 0" />
      <mass value="0.002" />
      <inertia ixx="1.00486658585813E-08" ixy="-7.87051809312931E-14" ixz="2.25917784171234E-09" iyy="8.23228109049258E-09" iyz="1.50825328552765E-13" izz="4.41272192206512E-09" />
    </inertial>
    <visual>
      <origin xyz="0 0 0" rpy="0 0 0" />
      <geometry>
        <mesh filename="meshes/right_middle_touch_link.STL" />
      </geometry>
      <material name="">
        <color rgba="1 1 1 1" />
      </material>
    </visual>
    <collision>
      <origin xyz="0 0 0" rpy="0 0 0" />
      <geometry>
        <mesh filename="meshes/right_middle_touch_link.STL" />
      </geometry>
    </collision>
  </link>
  <joint name="right_middle_touch_joint" type="fixed">
    <origin xyz="0.015975871997898 0 0.0265894268903603" rpy="0 0.475602221168456 0" />
    <parent link="right_middle_distal_link" />
    <child link="right_middle_touch_link" />
    <axis xyz="0 0 0" />
  </joint>
  <link name="right_ring_proximal_link">
    <inertial>
      <origin xyz="-0.00234494526421452 5.87954755621161E-06 0.019177402549597" rpy="0 0 0" />
      <mass value="0.009" />
      <inertia ixx="3.14177684848335E-07" ixy="3.34382331089976E-11" ixz="-7.78981780892183E-09" iyy="2.97613170150896E-07" iyz="2.41251871804457E-10" izz="1.0211543233675E-07" />
    </inertial>
    <visual>
      <origin xyz="0 0 0" rpy="0 0 0" />
      <geometry>
        <mesh filename="meshes/right_ring_proximal_link.STL" />
      </geometry>
      <material name="">
        <color rgba="1 1 1 1" />
      </material>
    </visual>
    <collision>
      <origin xyz="0 0 0" rpy="0 0 0" />
      <geometry>
        <mesh filename="meshes/right_ring_proximal_link.STL" />
      </geometry>
    </collision>
  </link>
  <joint name="right_ring_proximal_joint" type="revolute">
    <origin xyz="-0.0046709 -0.010026 0.083982" rpy="0.039462 0.14721 0.057932" />
    <parent link="right_base_link" />
    <child link="right_ring_proximal_link" />
    <axis xyz="0 1 0" />
    <limit lower="0" upper="1.41" effort="2" velocity="2.2685" />
  </joint>
  <link name="right_ring_distal_link">
    <inertial>
      <origin xyz="0.00382459959210406 7.8017874437751E-08 0.0160343764410312" rpy="0 0 0" />
      <mass value="0.009" />
      <inertia ixx="4.71792497420504E-07" ixy="-6.95225674723301E-13" ixz="-1.26948440940938E-07" iyy="5.06071998616974E-07" iyz="-2.19413968646526E-12" izz="1.15762768100302E-07" />
    </inertial>
    <visual>
      <origin xyz="0 0 0" rpy="0 0 0" />
      <geometry>
        <mesh filename="meshes/right_ring_distal_link.STL" />
      </geometry>
      <material name="">
        <color rgba="1 1 1 1" />
      </material>
    </visual>
    <collision>
      <origin xyz="0 0 0" rpy="0 0 0" />
      <geometry>
        <mesh filename="meshes/right_ring_distal_link.STL" />
      </geometry>
    </collision>
  </link>
  <joint name="right_ring_distal_joint" type="revolute">
    <origin xyz="0 0 0.035" rpy="0 0 0" />
    <parent link="right_ring_proximal_link" />
    <child link="right_ring_distal_link" />
    <axis xyz="0 1 0" />
    <limit lower="0" upper="1.63" effort="2" velocity="2.2685" />
    <mimic joint="right_ring_proximal_joint" multiplier="1.155" offset="0" />
  </joint>
  <link name="right_ring_tip_link">
    </link>
  <joint name="right_ring_tip_joint" type="fixed">
    <origin xyz="0.012266 0 0.039501" rpy="0 0.4756 0" />
    <parent link="right_ring_distal_link" />
    <child link="right_ring_tip_link" />
    <axis xyz="0 0 0" />
    </joint>
  <link name="right_ring_touch_link">
    <inertial>
      <origin xyz="-0.00302345770059939 -4.42584829375703E-08 0.0030407600788087" rpy="0 0 0" />
      <mass value="0.002" />
      <inertia ixx="8.20180993934663E-09" ixy="-2.63295949836146E-14" ixz="1.83211342144402E-09" iyy="6.63652036961065E-09" iyz="1.12534283673606E-13" izz="3.61925974724395E-09" />
    </inertial>
    <visual>
      <origin xyz="0 0 0" rpy="0 0 0" />
      <geometry>
        <mesh filename="meshes/right_ring_touch_link.STL" />
      </geometry>
      <material name="">
        <color rgba="1 1 1 1" />
      </material>
    </visual>
    <collision>
      <origin xyz="0 0 0" rpy="0 0 0" />
      <geometry>
        <mesh filename="meshes/right_ring_touch_link.STL" />
      </geometry>
    </collision>
  </link>
  <joint name="right_ring_touch_joint" type="fixed">
    <origin xyz="0.0154392324697935 0 0.0260561041381566" rpy="0 0.475602221168648 0" />
    <parent link="right_ring_distal_link" />
    <child link="right_ring_touch_link" />
    <axis xyz="0 0 0" />
  </joint>
  <link name="right_pinky_proximal_link">
    <inertial>
      <origin xyz="-0.00213212021184178 7.75039446098032E-06 0.0160671583560383" rpy="0 0 0" />
      <mass value="0.009" />
      <inertia ixx="1.97563213550085E-07" ixy="2.23402433057963E-11" ixz="-4.58425663692079E-09" iyy="1.82023043083307E-07" iyz="1.08028441152494E-10" izz="8.21624712033168E-08" />
    </inertial>
    <visual>
      <origin xyz="0 0 0" rpy="0 0 0" />
      <geometry>
        <mesh filename="meshes/right_pinky_proximal_link.STL" />
      </geometry>
      <material name="">
        <color rgba="1 1 1 1" />
      </material>
    </visual>
    <collision>
      <origin xyz="0 0 0" rpy="0 0 0" />
      <geometry>
        <mesh filename="meshes/right_pinky_proximal_link.STL" />
      </geometry>
    </collision>
  </link>
  <joint name="right_pinky_proximal_joint" type="revolute">
    <origin xyz="-0.0023566 -0.029366 0.078694" rpy="0.11815 0.14491 0.17392" />
    <parent link="right_base_link" />
    <child link="right_pinky_proximal_link" />
    <axis xyz="0 1 0" />
    <limit lower="0" upper="1.41" effort="2" velocity="2.2685" />
  </joint>
  <link name="right_pinky_distal_link">
    <inertial>
      <origin xyz="0.00307974197235919 -1.54572112227858E-07 0.0130246967256256" rpy="0 0 0" />
      <mass value="0.009" />
      <inertia ixx="2.70050429038431E-07" ixy="1.68029751000565E-12" ixz="-6.70780254430148E-08" iyy="2.85275081521347E-07" iyz="5.10635117768255E-12" izz="7.90798706854226E-08" />
    </inertial>
    <visual>
      <origin xyz="0 0 0" rpy="0 0 0" />
      <geometry>
        <mesh filename="meshes/right_pinky_distal_link.STL" />
      </geometry>
      <material name="">
        <color rgba="1 1 1 1" />
      </material>
    </visual>
    <collision>
      <origin xyz="0 0 0" rpy="0 0 0" />
      <geometry>
        <mesh filename="meshes/right_pinky_distal_link.STL" />
      </geometry>
    </collision>
  </link>
  <joint name="right_pinky_distal_joint" type="revolute">
    <origin xyz="0 0 0.029" rpy="0 0 0" />
    <parent link="right_pinky_proximal_link" />
    <child link="right_pinky_distal_link" />
    <axis xyz="0 1 0" />
    <limit lower="0" upper="1.63" effort="2" velocity="2.2685" />
    <mimic joint="right_pinky_proximal_joint" multiplier="1.155" offset="0" />
  </joint>
  <link name="right_pinky_tip_link">
    </link>
  <joint name="right_pinky_tip_joint" type="fixed">
    <origin xyz="0.010221 0 0.032918" rpy="0 0.4756 0" />
    <parent link="right_pinky_distal_link" />
    <child link="right_pinky_tip_link" />
    <axis xyz="0 0 0" />
    </joint>
  <link name="right_pinky_touch_link">
    <inertial>
      <origin xyz="-0.00289142401155668 -2.00563398826403E-07 0.00165387959177493" rpy="0 0 0" />
      <mass value="0.002" />
      <inertia ixx="6.91911795672566E-09" ixy="1.21758056374209E-13" ixz="1.42748611971717E-09" iyy="5.34364749688619E-09" iyz="7.16346527443829E-14" izz="3.28289727389894E-09" />
    </inertial>
    <visual>
      <origin xyz="0 0 0" rpy="0 0 0" />
      <geometry>
        <mesh filename="meshes/right_pinky_touch_link.STL" />
      </geometry>
      <material name="">
        <color rgba="1 1 1 1" />
      </material>
    </visual>
    <collision>
      <origin xyz="0 0 0" rpy="0 0 0" />
      <geometry>
        <mesh filename="meshes/right_pinky_touch_link.STL" />
      </geometry>
    </collision>
  </link>
  <joint name="right_pinky_touch_joint" type="fixed">
    <origin xyz="0.01401 0 0.021124" rpy="0 0.4756 0" />
    <parent link="right_pinky_distal_link" />
    <child link="right_pinky_touch_link" />
    <axis xyz="0 0 0" />
  </joint>
<!-- MID360 -->
  <link name="MID360_link">
    <visual>
      <origin xyz="0 0 0" rpy="0 0 0" />
      <geometry>
        <mesh filename="meshes/MID360_link.STL" />
      </geometry>
      <material name="">
        <color rgba="0 0.4 0.6 1" />
      </material>
    </visual>
  </link>
  <joint name="MID360_joint" type="fixed">
    <origin xyz="0 0 0.603" rpy="0 0 0" />
    <parent link="torso_link" />
    <child link="MID360_link" />
    <axis xyz="0 0 0" />
  </joint>
<!-- D435 -->
  <link name="D435_link">
    <visual>
      <origin xyz="0 0 0" rpy="0 0 0" />
      <geometry>
        <mesh filename="meshes/D435_link.STL" />
      </geometry>
      <material name="">
        <color rgba="0 0 0 0.6" />
      </material>
    </visual>
  </link>
  <joint name="D435_joint" type="fixed">
    <origin xyz="0.057928 0 0.59381" rpy="0 0.95993 0" />
    <parent link="torso_link" />
    <child link="D435_link" />
    <axis xyz="0 0 0" />
  </joint>
<!-- Camera -->
  <link name="Camera_link">
    <visual>
      <origin xyz="0 0 0" rpy="0 0 0" />
      <geometry>
        <mesh filename="meshes/Camera_link.STL" />
      </geometry>
      <material name="">
        <color rgba="0 0 0 0.6" />
      </material>
    </visual>
  </link>
  <joint name="Camera_joint" type="fixed">
    <origin xyz="0.04205 0 0.6345" rpy="0 0.2618 0" />
    <parent link="torso_link" />
    <child link="Camera_link" />
    <axis xyz="0 0 0" />
  </joint>
</robot>