<mujoco model="x2">
  <compiler angle="radian" meshdir="./meshes/"/>
  <statistic meansize="0.177939" extent="1.9618" center="0.0465088 1.93584e-06 -0.21519"/>
  <default>
    <joint damping="0.1" armature="0.01" frictionloss="0.1"/>
  </default>
  <asset>
    <texture type="skybox" builtin="gradient" width="128" height="128" rgb1="0.4 0.6 0.8" rgb2="0 0 0"/>
    <texture name="plane" type="2d" builtin="checker" rgb1="0.2 0.2 0.2" rgb2="0.3 0.3 0.3" width="512"
              height="512"/>
    <material name="plane" reflectance="0.0" texture="plane" texrepeat="1 1" texuniform="true"/>
    <mesh name="pelvis" file="pelvis.STL"/>
    <mesh name="left_hip_yaw_link" file="left_hip_yaw_link.STL"/>
    <mesh name="left_hip_roll_link" file="left_hip_roll_link.STL"/>
    <mesh name="left_hip_pitch_link" file="left_hip_pitch_link.STL"/>
    <mesh name="left_knee_link" file="left_knee_link.STL"/>
    <mesh name="left_ankle_pitch_link" file="left_ankle_pitch_link.STL"/>
    <mesh name="left_ankle_roll_link" file="left_ankle_roll_link.STL"/>
    <mesh name="right_hip_yaw_link" file="right_hip_yaw_link.STL"/>
    <mesh name="right_hip_roll_link" file="right_hip_roll_link.STL"/>
    <mesh name="right_hip_pitch_link" file="right_hip_pitch_link.STL"/>
    <mesh name="right_knee_link" file="right_knee_link.STL"/>
    <mesh name="right_ankle_pitch_link" file="right_ankle_pitch_link.STL"/>
    <mesh name="right_ankle_roll_link" file="right_ankle_roll_link.STL"/>
    <mesh name="torso_link" file="torso_link.STL"/>
    <mesh name="logo_link" file="logo_link.STL"/>
    <mesh name="LiDARhead_link" file="LiDARhead_link.STL"/>
    <mesh name="left_shoulder_pitch_link" file="left_shoulder_pitch_link.STL"/>
    <mesh name="left_shoulder_roll_link" file="left_shoulder_roll_link.STL"/>
    <mesh name="left_shoulder_yaw_link" file="left_shoulder_yaw_link.STL"/>
    <mesh name="left_elbow_link" file="left_elbow_link.STL"/>
    <mesh name="left_wrist_roll_link" file="left_wrist_roll_link.STL"/>
    <mesh name="left_base_link" file="left_base_link.STL"/>
    <mesh name="left_thumb_metacarpal_link" file="left_thumb_metacarpal_link.STL"/>
    <mesh name="left_thumb_proximal_link" file="left_thumb_proximal_link.STL"/>
    <mesh name="left_thumb_proximal_visual_link" file="left_thumb_proximal_visual_link.STL"/>
    <mesh name="left_thumb_distal_link" file="left_thumb_distal_link.STL"/>
    <mesh name="left_thumb_touch_link" file="left_thumb_touch_link.STL"/>
    <mesh name="left_index_proximal_link" file="left_index_proximal_link.STL"/>
    <mesh name="left_index_distal_link" file="left_index_distal_link.STL"/>
    <mesh name="left_index_touch_link" file="left_index_touch_link.STL"/>
    <mesh name="left_middle_proximal_link" file="left_middle_proximal_link.STL"/>
    <mesh name="left_middle_distal_link" file="left_middle_distal_link.STL"/>
    <mesh name="left_middle_touch_link" file="left_middle_touch_link.STL"/>
    <mesh name="left_ring_proximal_link" file="left_ring_proximal_link.STL"/>
    <mesh name="left_ring_distal_link" file="left_ring_distal_link.STL"/>
    <mesh name="left_ring_touch_link" file="left_ring_touch_link.STL"/>
    <mesh name="left_pinky_proximal_link" file="left_pinky_proximal_link.STL"/>
    <mesh name="left_pinky_distal_link" file="left_pinky_distal_link.STL"/>
    <mesh name="left_pinky_touch_link" file="left_pinky_touch_link.STL"/>
    <mesh name="right_shoulder_pitch_link" file="right_shoulder_pitch_link.STL"/>
    <mesh name="right_shoulder_roll_link" file="right_shoulder_roll_link.STL"/>
    <mesh name="right_shoulder_yaw_link" file="right_shoulder_yaw_link.STL"/>
    <mesh name="right_elbow_link" file="right_elbow_link.STL"/>
    <mesh name="right_wrist_roll_link" file="right_wrist_roll_link.STL"/>
    <mesh name="right_base_link" file="right_base_link.STL"/>
    <mesh name="right_thumb_metacarpal_link" file="right_thumb_metacarpal_link.STL"/>
    <mesh name="right_thumb_proximal_visual_link" file="right_thumb_proximal_visual_link.STL"/>
    <mesh name="right_thumb_proximal_link" file="right_thumb_proximal_link.STL"/>
    <mesh name="right_thumb_distal_link" file="right_thumb_distal_link.STL"/>
    <mesh name="right_thumb_touch_link" file="right_thumb_touch_link.STL"/>
    <mesh name="right_index_proximal_link" file="right_index_proximal_link.STL"/>
    <mesh name="right_index_distal_link" file="right_index_distal_link.STL"/>
    <mesh name="right_index_touch_link" file="right_index_touch_link.STL"/>
    <mesh name="right_middle_proximal_link" file="right_middle_proximal_link.STL"/>
    <mesh name="right_middle_distal_link" file="right_middle_distal_link.STL"/>
    <mesh name="right_middle_touch_link" file="right_middle_touch_link.STL"/>
    <mesh name="right_ring_proximal_link" file="right_ring_proximal_link.STL"/>
    <mesh name="right_ring_distal_link" file="right_ring_distal_link.STL"/>
    <mesh name="right_ring_touch_link" file="right_ring_touch_link.STL"/>
    <mesh name="right_pinky_proximal_link" file="right_pinky_proximal_link.STL"/>
    <mesh name="right_pinky_distal_link" file="right_pinky_distal_link.STL"/>
    <mesh name="right_pinky_touch_link" file="right_pinky_touch_link.STL"/>
    <mesh name="MID360_link" file="MID360_link.STL"/>
    <mesh name="D435_link" file="D435_link.STL"/>
    <mesh name="Camera_link" file="Camera_link.STL"/>
  </asset>

  <worldbody>
    <geom name="floor" pos="0.001 0 0" size="100 10 .125" type="plane" material="plane" condim="3"
          conaffinity="15" friction="0.6 0.6 0.001"/>
    <light mode="trackcom" pos="0 0 5" dir="0 0 -1"/>
    <body name="pelvis" pos="0 0 1.042">
      <inertial pos="-0.00225183 -2.88276e-06 0.264928" quat="0.999858 2.16978e-06 0.0168347 -1.84125e-05" mass="13.05" diaginertia="0.511828 0.493563 0.0995275"/>
      <joint name="pelvis" type="free" limited="false" actuatorfrclimited="false"/>
      <geom type="mesh" contype="0" conaffinity="0" group="1" density="0" rgba="0.45 0.45 0.45 1" mesh="pelvis"/>
      <geom type="mesh" rgba="0.45 0.45 0.45 1" mesh="pelvis"/>
      <geom type="mesh" contype="0" conaffinity="0" group="1" density="0" rgba="1.43 1.43 1.43 1" mesh="torso_link"/>
      <geom type="mesh" rgba="1.43 1.43 1.43 1" mesh="torso_link"/>
      <geom type="mesh" contype="0" conaffinity="0" group="1" density="0" rgba="0 0 0 1" mesh="logo_link"/>
      <geom pos="-0.01 0 0.3575" quat="1 0 0 0" type="mesh" contype="0" conaffinity="0" group="1" density="0" rgba="1 1 1 1" mesh="LiDARhead_link"/>
      <geom pos="-0.01 0 0.3575" quat="1 0 0 0" type="mesh" rgba="1 1 1 1" mesh="LiDARhead_link"/>
      <geom pos="0 0 0.603" quat="1 0 0 0" type="mesh" contype="0" conaffinity="0" group="1" density="0" rgba="0 0.4 0.6 1" mesh="MID360_link"/>
      <geom pos="0.057928 0 0.59381" quat="0.887011 0 0.461748 0" type="mesh" contype="0" conaffinity="0" group="1" density="0" rgba="0 0 0 0.6" mesh="D435_link"/>
      <geom pos="0.04205 0 0.6345" quat="0.991445 0 0.130526 0" type="mesh" contype="0" conaffinity="0" group="1" density="0" rgba="0 0 0 0.6" mesh="Camera_link"/>
      <body name="left_hip_yaw_link" pos="0 0 -0.1315">
        <inertial pos="0 0.01346 0.0446415" quat="0.972798 0.231653 0 0" mass="1.741" diaginertia="0.0065201 0.00517562 0.00284105"/>
        <joint name="left_hip_yaw_joint" pos="0 0 0" axis="0 0 1" range="-0.393 0.393" actuatorfrcrange="-50 50"/>
        <geom type="mesh" contype="0" conaffinity="0" group="1" density="0" rgba="0.41961 0.41961 0.41961 1" mesh="left_hip_yaw_link"/>
        <body name="left_hip_roll_link" pos="0 0.12 -0.001">
          <inertial pos="-0.034584 0.00017707 -0.071764" quat="0.68852 0.164795 0.159084 0.688095" mass="2.667" diaginertia="0.0112939 0.0106495 0.00649981"/>
          <joint name="left_hip_roll_joint" pos="0 0 0" axis="1 0 0" range="-0.349 0.534" actuatorfrcrange="-100 100"/>
          <geom type="mesh" contype="0" conaffinity="0" group="1" density="0" rgba="0.41961 0.41961 0.41961 1" mesh="left_hip_roll_link"/>
          <geom type="mesh" rgba="0.41961 0.41961 0.41961 1" mesh="left_hip_roll_link"/>
          <body name="left_hip_pitch_link" pos="0 0 -0.11">
            <inertial pos="0.0082287 0 -0.167031" quat="0.706936 0.0155262 0.0155262 0.706936" mass="1.8" diaginertia="0.0177056 0.017016 0.00316021"/>
            <joint name="left_hip_pitch_joint" pos="0 0 0" axis="0 1 0" range="-2.094 0.534" actuatorfrcrange="-212 212"/>
            <geom type="mesh" contype="0" conaffinity="0" group="1" density="0" rgba="1.43 1.43 1.43 1" mesh="left_hip_pitch_link"/>
            <geom type="mesh" rgba="1.43 1.43 1.43 1" mesh="left_hip_pitch_link"/>
            <body name="left_knee_link" pos="0 0 -0.35">
              <inertial pos="0.00111166 0 -0.146097" quat="0.707021 -0.0110178 -0.0110178 0.707021" mass="1.125" diaginertia="0.0117203 0.0115906 0.00120819"/>
              <joint name="left_knee_joint" pos="0 0 0" axis="0 1 0" range="0 2.269" actuatorfrcrange="-93 93"/>
              <geom type="mesh" contype="0" conaffinity="0" group="1" density="0" rgba="1.43 1.43 1.43 1" mesh="left_knee_link"/>
              <geom type="mesh" rgba="1.43 1.43 1.43 1" mesh="left_knee_link"/>
              <body name="left_ankle_pitch_link" pos="0 0 -0.35">
                <inertial pos="0 0 -0.0372041" quat="0.707107 0 0 0.707107" mass="0.2" diaginertia="0.000212196 0.00019348 7.03112e-05"/>
                <joint name="left_ankle_pitch_joint" pos="0 0 0" axis="0 1 0" range="-1.047 1.047" actuatorfrcrange="-64.8 64.8"/>
                <geom type="mesh" contype="0" conaffinity="0" group="1" density="0" rgba="0.419608 0.419608 0.419608 1" mesh="left_ankle_pitch_link"/>
                <geom type="mesh" rgba="0.419608 0.419608 0.419608 1" mesh="left_ankle_pitch_link"/>
                <body name="left_ankle_roll_link" pos="0 0 -0.058">
                  <inertial pos="0.048712 -7.42e-06 -0.00856332" quat="-8.7305e-07 0.72444 5.08669e-06 0.689338" mass="1" diaginertia="0.00705027 0.0065554 0.000767487"/>
                  <joint name="left_ankle_roll_joint" pos="0 0 0" axis="1 0 0" range="-0.5236 0.5236" actuatorfrcrange="-7.7 7.7"/>
                  <geom type="mesh" contype="0" conaffinity="0" group="1" density="0" rgba="1.43 1.43 1.43 1" mesh="left_ankle_roll_link"/>
                  <geom size="0.005" pos="-0.085 0 -0.036" rgba="1.43 1.43 1.43 1"/>
                  <geom size="0.005" pos="-0.035 0.034 -0.036" rgba="1.43 1.43 1.43 1"/>
                  <geom size="0.005" pos="-0.035 -0.034 -0.036" rgba="1.43 1.43 1.43 1"/>
                  <geom size="0.005" pos="0.12 0.045 -0.036" rgba="1.43 1.43 1.43 1"/>
                  <geom size="0.005" pos="0.12 -0.045 -0.036" rgba="1.43 1.43 1.43 1"/>
                  <geom size="0.005" pos="0.18 0 -0.036" rgba="1.43 1.43 1.43 1"/>
                  <geom size="0.01 0.05" pos="0.08 -0.026 -0.024" quat="0.707105 0 0.707108 0" type="cylinder" rgba="1.43 1.43 1.43 1"/>
                  <geom size="0.01 0.1" pos="0.044 -0.018 -0.024" quat="0.707105 0 -0.707108 0" type="cylinder" rgba="1.43 1.43 1.43 1"/>
                  <geom size="0.01 0.12" pos="0.046 -0.01 -0.024" quat="0.707105 0 -0.707108 0" type="cylinder" rgba="1.43 1.43 1.43 1"/>
                  <geom size="0.01 0.125" pos="0.048 0 -0.024" quat="0.707105 0 -0.707108 0" type="cylinder" rgba="1.43 1.43 1.43 1"/>
                  <geom size="0.01 0.12" pos="0.046 0.01 -0.024" quat="0.707105 0 -0.707108 0" type="cylinder" rgba="1.43 1.43 1.43 1"/>
                  <geom size="0.01 0.1" pos="0.044 0.018 -0.024" quat="0.707105 0 -0.707108 0" type="cylinder" rgba="1.43 1.43 1.43 1"/>
                  <geom size="0.01 0.05" pos="0.08 0.026 -0.024" quat="0.707105 0 0.707108 0" type="cylinder" rgba="1.43 1.43 1.43 1"/>
                </body>
              </body>
            </body>
          </body>
        </body>
      </body>
      <body name="right_hip_yaw_link" pos="0 0 -0.1315">
        <inertial pos="0 -0.050494 0.006108" quat="0.722974 0.690875 0 0" mass="0.947" diaginertia="0.00267262 0.00231924 0.000763015"/>
        <joint name="right_hip_yaw_joint" pos="0 0 0" axis="0 0 1" range="-0.393 0.393" actuatorfrcrange="-50 50"/>
        <geom type="mesh" contype="0" conaffinity="0" group="1" density="0" rgba="0.41961 0.41961 0.41961 1" mesh="right_hip_yaw_link"/>
        <body name="right_hip_roll_link" pos="0 -0.12 -0.001">
          <inertial pos="-0.034584 -0.00017759 -0.071763" quat="0.688098 0.159077 0.164778 0.688523" mass="2.667" diaginertia="0.0112941 0.0106496 0.0064998"/>
          <joint name="right_hip_roll_joint" pos="0 0 0" axis="1 0 0" range="-0.534 0.349" actuatorfrcrange="-100 100"/>
          <geom type="mesh" contype="0" conaffinity="0" group="1" density="0" rgba="0.41961 0.41961 0.41961 1" mesh="right_hip_roll_link"/>
          <geom type="mesh" rgba="0.41961 0.41961 0.41961 1" mesh="right_hip_roll_link"/>
          <body name="right_hip_pitch_link" pos="0 0 -0.11">
            <inertial pos="0.0082287 0 -0.167031" quat="0.706937 0.0155252 0.0155272 0.706935" mass="1.8" diaginertia="0.0177056 0.017016 0.0031602"/>
            <joint name="right_hip_pitch_joint" pos="0 0 0" axis="0 1 0" range="-2.094 0.534" actuatorfrcrange="-212 212"/>
            <geom type="mesh" contype="0" conaffinity="0" group="1" density="0" rgba="1.43 1.43 1.43 1" mesh="right_hip_pitch_link"/>
            <geom type="mesh" rgba="1.43 1.43 1.43 1" mesh="right_hip_pitch_link"/>
            <body name="right_knee_link" pos="0 0 -0.35">
              <inertial pos="0.00111164 0 -0.146097" quat="0.707021 -0.0110174 -0.0110174 0.707021" mass="1.125" diaginertia="0.0117203 0.0115906 0.00120819"/>
              <joint name="right_knee_joint" pos="0 0 0" axis="0 1 0" range="0 2.269" actuatorfrcrange="-93 93"/>
              <geom type="mesh" contype="0" conaffinity="0" group="1" density="0" rgba="1.43 1.43 1.43 1" mesh="right_knee_link"/>
              <geom type="mesh" rgba="1.43 1.43 1.43 1" mesh="right_knee_link"/>
              <body name="right_ankle_pitch_link" pos="0 0 -0.35">
                <inertial pos="0 0 -0.0372041" quat="0.707107 0 0 0.707107" mass="0.2" diaginertia="0.000212196 0.00019348 7.03112e-05"/>
                <joint name="right_ankle_pitch_joint" pos="0 0 0" axis="0 1 0" range="-1.047 1.047" actuatorfrcrange="-64.8 64.8"/>
                <geom type="mesh" contype="0" conaffinity="0" group="1" density="0" rgba="0.419608 0.419608 0.419608 1" mesh="right_ankle_pitch_link"/>
                <geom type="mesh" rgba="0.419608 0.419608 0.419608 1" mesh="right_ankle_pitch_link"/>
                <body name="right_ankle_roll_link" pos="0 0 -0.058">
                  <inertial pos="0.048712 -7.42e-06 -0.00856332" quat="-8.57829e-07 0.72444 5.09281e-06 0.689338" mass="1" diaginertia="0.00705025 0.00655536 0.00076749"/>
                  <joint name="right_ankle_roll_joint" pos="0 0 0" axis="1 0 0" range="-0.5236 0.5236" actuatorfrcrange="-7.7 7.7"/>
                  <geom type="mesh" contype="0" conaffinity="0" group="1" density="0" rgba="1.43 1.43 1.43 1" mesh="right_ankle_roll_link"/>
                  <geom size="0.005" pos="-0.085 0 -0.036" rgba="1.43 1.43 1.43 1"/>
                  <geom size="0.005" pos="-0.035 0.034 -0.036" rgba="1.43 1.43 1.43 1"/>
                  <geom size="0.005" pos="-0.035 -0.034 -0.036" rgba="1.43 1.43 1.43 1"/>
                  <geom size="0.005" pos="0.12 0.045 -0.036" rgba="1.43 1.43 1.43 1"/>
                  <geom size="0.005" pos="0.12 -0.045 -0.036" rgba="1.43 1.43 1.43 1"/>
                  <geom size="0.005" pos="0.18 0 -0.036" rgba="1.43 1.43 1.43 1"/>
                  <geom size="0.01 0.05" pos="0.08 -0.026 -0.024" quat="0.707105 0 0.707108 0" type="cylinder" rgba="1.43 1.43 1.43 1"/>
                  <geom size="0.01 0.1" pos="0.044 -0.018 -0.024" quat="0.707105 0 -0.707108 0" type="cylinder" rgba="1.43 1.43 1.43 1"/>
                  <geom size="0.01 0.12" pos="0.046 -0.01 -0.024" quat="0.707105 0 -0.707108 0" type="cylinder" rgba="1.43 1.43 1.43 1"/>
                  <geom size="0.01 0.125" pos="0.048 0 -0.024" quat="0.707105 0 -0.707108 0" type="cylinder" rgba="1.43 1.43 1.43 1"/>
                  <geom size="0.01 0.12" pos="0.046 0.01 -0.024" quat="0.707105 0 -0.707108 0" type="cylinder" rgba="1.43 1.43 1.43 1"/>
                  <geom size="0.01 0.1" pos="0.044 0.018 -0.024" quat="0.707105 0 -0.707108 0" type="cylinder" rgba="1.43 1.43 1.43 1"/>
                  <geom size="0.01 0.05" pos="0.08 0.026 -0.024" quat="0.707105 0 0.707108 0" type="cylinder" rgba="1.43 1.43 1.43 1"/>
                </body>
              </body>
            </body>
          </body>
        </body>
      </body>
      <body name="left_shoulder_pitch_link" pos="-0.01 0.13365 0.31135" quat="0.996195 0.0871543 0 0">
        <inertial pos="0 0.0291327 0" quat="0 0.707107 0 0.707107" mass="0.276" diaginertia="0.00033854 0.00021249 0.00019627"/>
        <joint name="left_shoulder_pitch_joint" pos="0 0 0" axis="0 1 0" range="-2.749 2.749" actuatorfrcrange="-18 18"/>
        <geom type="mesh" contype="0" conaffinity="0" group="1" density="0" rgba="0.419608 0.419608 0.419608 1" mesh="left_shoulder_pitch_link"/>
        <body name="left_shoulder_roll_link" pos="0 0.0588 0" quat="0.996195 -0.0871543 0 0">
          <inertial pos="0.00013265 0.00797093 -0.0452124" quat="0.996194 0.0871559 -0.00108264 -8.46243e-05" mass="1.126" diaginertia="0.00147896 0.00143617 0.000604058"/>
          <joint name="left_shoulder_roll_joint" pos="0 0 0" axis="1 0 0" range="-0.175 2.653" actuatorfrcrange="-14 14"/>
          <geom type="mesh" contype="0" conaffinity="0" group="1" density="0" rgba="1.43 1.43 1.43 1" mesh="left_shoulder_roll_link"/>
          <geom type="mesh" rgba="1.43 1.43 1.43 1" mesh="left_shoulder_roll_link"/>
          <body name="left_shoulder_yaw_link" pos="0 0.018928 -0.10734" quat="0.996195 0.0871543 0 0">
            <inertial pos="-0.00093704 0 -0.0773534" quat="0.999861 -9.26162e-06 0.0166815 9.57554e-06" mass="0.896" diaginertia="0.00233046 0.00227734 0.00068588"/>
            <joint name="left_shoulder_yaw_joint" pos="0 0 0" axis="0 0 1" range="-2.618 2.618" actuatorfrcrange="-14 14"/>
            <geom type="mesh" contype="0" conaffinity="0" group="1" density="0" rgba="1.43 1.43 1.43 1" mesh="left_shoulder_yaw_link"/>
            <geom type="mesh" rgba="1.43 1.43 1.43 1" mesh="left_shoulder_yaw_link"/>
            <body name="left_elbow_link" pos="0.01 0 -0.151">
              <inertial pos="0.0945565 -1.42e-06 -0.0109687" quat="0 0.726686 0 0.68697" mass="0.576" diaginertia="0.00169287 0.00166798 0.000367392"/>
              <joint name="left_elbow_joint" pos="0 0 0" axis="0 1 0" range="-0.873 1.571" actuatorfrcrange="-14 14"/>
              <geom type="mesh" contype="0" conaffinity="0" group="1" density="0" rgba="1.43 1.43 1.43 1" mesh="left_elbow_link"/>
              <geom type="mesh" rgba="1.43 1.43 1.43 1" mesh="left_elbow_link"/>
              <body name="left_wrist_roll_link" pos="0.201 0 -0.01" quat="0.996195 -0.0871543 0 0">
                <inertial pos="0.0730253 -0.00113088 0.0031915" quat="0.384169 0.615076 0.277973 0.629942" mass="0.93" diaginertia="0.000680964 0.000531895 0.000229303"/>
                <joint name="left_wrist_roll_joint" pos="0 0 0" axis="1 0 0" range="-2.662 2.662" actuatorfrcrange="-2.2 2.2"/>
                <geom type="mesh" contype="0" conaffinity="0" group="1" density="0" rgba="0.419608 0.419608 0.419608 1" mesh="left_wrist_roll_link"/>
                <geom type="mesh" rgba="0.419608 0.419608 0.419608 1" mesh="left_wrist_roll_link"/>
                <geom pos="0.015 0 0" quat="0.499998 -0.5 0.500002 -0.5" type="mesh" contype="0" conaffinity="0" group="1" density="0" rgba="1 1 1 1" mesh="left_base_link"/>
                <geom pos="0.015 0 0" quat="0.499998 -0.5 0.500002 -0.5" type="mesh" rgba="1 1 1 1" mesh="left_base_link"/>
                <body name="left_thumb_metacarpal_link" pos="0.0428251 -0.0056191 0.0198669" quat="0.540156 -0.456321 0.54016 -0.456322">
                  <inertial pos="1.51106e-05 -0.00707243 -0.00420847" quat="0.465075 -0.0302438 0.0586743 0.882807" mass="0.01" diaginertia="1.66115e-07 1.56006e-07 4.9387e-08"/>
                  <joint name="left_thumb_metacarpal_joint" pos="0 0 0" axis="0 0 1" range="0 1.57" actuatorfrcrange="-0.5 0.5"/>
                  <geom type="mesh" contype="0" conaffinity="0" group="1" density="0" rgba="1 1 1 1" mesh="left_thumb_metacarpal_link"/>
                  <geom type="mesh" rgba="1 1 1 1" mesh="left_thumb_metacarpal_link"/>
                  <body name="left_thumb_proximal_link" pos="0 -0.014227 0" quat="0.986557 -0.0765206 0.124804 -0.0726253">
                    <inertial pos="-4.6972e-07 -0.0277015 -0.00202656" quat="0.496496 0.503512 -0.503514 0.496429" mass="0.05" diaginertia="2.56295e-06 2.40452e-06 5.11916e-07"/>
                    <joint name="left_thumb_proximal_joint" pos="0 0 0" axis="-1 0 0" range="0 1.03" actuatorfrcrange="-1.1 1.1"/>
                    <geom type="mesh" contype="0" conaffinity="0" group="1" density="0" rgba="1 1 1 1" mesh="left_thumb_proximal_link"/>
                    <geom type="mesh" contype="0" conaffinity="0" group="1" density="0" rgba="1 1 1 1" mesh="left_thumb_proximal_visual_link"/>
                    <geom type="mesh" rgba="1 1 1 1" mesh="left_thumb_proximal_link"/>
                    <body name="left_thumb_distal_link" pos="0 -0.052 0">
                      <inertial pos="-6.86982e-09 -0.0116258 5.41195e-05" quat="0.498813 0.501127 -0.50111 0.498945" mass="0.012" diaginertia="4.39955e-07 3.36691e-07 2.30979e-07"/>
                      <joint name="left_thumb_distal_joint" pos="0 0 0" axis="-1 0 0" range="0 1.03" actuatorfrcrange="-1.1 1.1"/>
                      <geom type="mesh" contype="0" conaffinity="0" group="1" density="0" rgba="1 1 1 1" mesh="left_thumb_distal_link"/>
                      <geom type="mesh" rgba="1 1 1 1" mesh="left_thumb_distal_link"/>
                      <geom pos="0 -0.013836 0.0076686" quat="0.99618 0.0873286 0 0" type="mesh" contype="0" conaffinity="0" group="1" density="0" rgba="1 1 1 1" mesh="left_thumb_touch_link"/>
                      <geom pos="0 -0.013836 0.0076686" quat="0.99618 0.0873286 0 0" type="mesh" rgba="1 1 1 1" mesh="left_thumb_touch_link"/>
                    </body>
                  </body>
                </body>
                <body name="left_index_proximal_link" pos="0.0958761 0.0021346 0.0295777" quat="0.524169 -0.389611 0.550257 -0.520257">
                  <inertial pos="-0.00223495 -3.15875e-06 0.0176402" quat="0.9998 0.000578854 0.0200071 0.00015863" mass="0.009" diaginertia="2.52201e-07 2.36436e-07 9.27798e-08"/>
                  <joint name="left_index_proximal_joint" pos="0 0 0" axis="0 1 0" range="0 1.41" actuatorfrcrange="-2 2"/>
                  <geom type="mesh" contype="0" conaffinity="0" group="1" density="0" rgba="1 1 1 1" mesh="left_index_proximal_link"/>
                  <geom type="mesh" rgba="1 1 1 1" mesh="left_index_proximal_link"/>
                  <body name="left_index_distal_link" pos="0 0 0.032">
                    <inertial pos="0.00482234 -0.000454225 0.0160526" quat="0.870991 0.150716 0.197065 0.424058" mass="0.011" diaginertia="6.62484e-07 6.37377e-07 9.50788e-08"/>
                    <joint name="left_index_distal_joint" pos="0 0 0" axis="0 1 0" range="0 1.63" actuatorfrcrange="-2 2"/>
                    <geom type="mesh" contype="0" conaffinity="0" group="1" density="0" rgba="1 1 1 1" mesh="left_index_distal_link"/>
                    <geom type="mesh" rgba="1 1 1 1" mesh="left_index_distal_link"/>
                    <geom pos="0.014497 0 0.023303" quat="0.971859 0 0.235565 0" type="mesh" contype="0" conaffinity="0" group="1" density="0" rgba="1 1 1 1" mesh="left_index_touch_link"/>
                    <geom pos="0.014497 0 0.023303" quat="0.971859 0 0.235565 0" type="mesh" rgba="1 1 1 1" mesh="left_index_touch_link"/>
                  </body>
                </body>
                <body name="left_middle_proximal_link" pos="0.0999931 0.00457639 0.0100507" quat="0.483516 -0.438557 0.540603 -0.530688">
                  <inertial pos="-0.00222511 -5.25632e-06 0.0203008" quat="0.999816 0.00054813 0.0191911 0.000563992" mass="0.009" diaginertia="3.67373e-07 3.52646e-07 1.11857e-07"/>
                  <joint name="left_middle_proximal_joint" pos="0 0 0" axis="0 1 0" range="0 1.41" actuatorfrcrange="-2 2"/>
                  <geom type="mesh" contype="0" conaffinity="0" group="1" density="0" rgba="1 1 1 1" mesh="left_middle_proximal_link"/>
                  <geom type="mesh" rgba="1 1 1 1" mesh="left_middle_proximal_link"/>
                  <body name="left_middle_distal_link" pos="0 0 0.037" quat="0.997999 0 0.0632278 0">
                    <inertial pos="0.00519057 2.75379e-08 0.0193677" quat="0.985061 2.94164e-05 0.172208 0.000161494" mass="0.011" diaginertia="1.04108e-06 1.03508e-06 8.65118e-08"/>
                    <joint name="left_middle_distal_joint" pos="0 0 0" axis="0 1 0" range="0 1.63" actuatorfrcrange="-2 2"/>
                    <geom type="mesh" contype="0" conaffinity="0" group="1" density="0" rgba="1 1 1 1" mesh="left_middle_distal_link"/>
                    <geom type="mesh" rgba="1 1 1 1" mesh="left_middle_distal_link"/>
                    <geom pos="0.012493 0 0.028393" quat="0.984807 0 0.17365 0" type="mesh" contype="0" conaffinity="0" group="1" density="0" rgba="1 1 1 1" mesh="left_middle_touch_link"/>
                    <geom pos="0.012493 0 0.028393" quat="0.984807 0 0.17365 0" type="mesh" rgba="1 1 1 1" mesh="left_middle_touch_link"/>
                  </body>
                </body>
                <body name="left_ring_proximal_link" pos="0.098982 0.00468739 -0.0100263" quat="0.438844 -0.483813 0.53045 -0.540337">
                  <inertial pos="-0.00234495 -5.87955e-06 0.0191774" quat="0.999831 0.000632097 0.0183324 0.000717657" mass="0.009" diaginertia="3.14463e-07 2.97613e-07 1.01829e-07"/>
                  <joint name="left_ring_proximal_joint" pos="0 0 0" axis="0 1 0" range="0 1.41" actuatorfrcrange="-2 2"/>
                  <geom type="mesh" contype="0" conaffinity="0" group="1" density="0" rgba="1 1 1 1" mesh="left_ring_proximal_link"/>
                  <geom type="mesh" rgba="1 1 1 1" mesh="left_ring_proximal_link"/>
                  <body name="left_ring_distal_link" pos="0 0 0.035" quat="0.997999 0 0.0632278 0">
                    <inertial pos="0.00498865 -5.57858e-08 0.0188804" quat="0.984874 -3.10641e-06 0.173274 5.46527e-07" mass="0.011" diaginertia="9.87244e-07 9.80723e-07 8.01464e-08"/>
                    <joint name="left_ring_distal_joint" pos="0 0 0" axis="0 1 0" range="0 1.63" actuatorfrcrange="-2 2"/>
                    <geom type="mesh" contype="0" conaffinity="0" group="1" density="0" rgba="1 1 1 1" mesh="left_ring_distal_link"/>
                    <geom type="mesh" rgba="1 1 1 1" mesh="left_ring_distal_link"/>
                    <geom pos="0.012028 0 0.027796" quat="0.984807 0 0.17365 0" type="mesh" contype="0" conaffinity="0" group="1" density="0" rgba="1 1 1 1" mesh="left_ring_touch_link"/>
                    <geom pos="0.012028 0 0.027796" quat="0.984807 0 0.17365 0" type="mesh" rgba="1 1 1 1" mesh="left_ring_touch_link"/>
                  </body>
                </body>
                <body name="left_pinky_proximal_link" pos="0.0936939 0.00235631 -0.0293663" quat="0.390267 -0.52487 0.519764 -0.549589">
                  <inertial pos="-0.00213212 -7.75039e-06 0.0160672" quat="0.999803 0.000555178 0.0198191 0.000562874" mass="0.009" diaginertia="1.97745e-07 1.82023e-07 8.19805e-08"/>
                  <joint name="left_pinky_proximal_joint" pos="0 0 0" axis="0 1 0" range="0 1.41" actuatorfrcrange="-2 2"/>
                  <geom type="mesh" contype="0" conaffinity="0" group="1" density="0" rgba="1 1 1 1" mesh="left_pinky_proximal_link"/>
                  <geom type="mesh" rgba="1 1 1 1" mesh="left_pinky_proximal_link"/>
                  <body name="left_pinky_distal_link" pos="0 0 0.029">
                    <inertial pos="0.00473738 1.62934e-07 0.0150053" quat="0.682043 0.18648 0.186455 0.682113" mass="0.011" diaginertia="6.20818e-07 6.07614e-07 8.1918e-08"/>
                    <joint name="left_pinky_distal_joint" pos="0 0 0" axis="0 1 0" range="0 1.63" actuatorfrcrange="-2 2"/>
                    <geom type="mesh" contype="0" conaffinity="0" group="1" density="0" rgba="1 1 1 1" mesh="left_pinky_distal_link"/>
                    <geom type="mesh" rgba="1 1 1 1" mesh="left_pinky_distal_link"/>
                    <geom pos="0.01401 0 0.021124" quat="0.971859 0 0.235565 0" type="mesh" contype="0" conaffinity="0" group="1" density="0" rgba="1 1 1 1" mesh="left_pinky_touch_link"/>
                    <geom pos="0.01401 0 0.021124" quat="0.971859 0 0.235565 0" type="mesh" rgba="1 1 1 1" mesh="left_pinky_touch_link"/>
                  </body>
                </body>
              </body>
            </body>
          </body>
        </body>
      </body>
      <body name="right_shoulder_pitch_link" pos="-0.01 -0.13365 0.31135" quat="0.996195 -0.0871543 0 0">
        <inertial pos="0 -0.0291327 0" quat="0 0.707107 0 0.707107" mass="0.276" diaginertia="0.00033854 0.00021249 0.00019627"/>
        <joint name="right_shoulder_pitch_joint" pos="0 0 0" axis="0 1 0" range="-2.749 2.749" actuatorfrcrange="-18 18"/>
        <geom type="mesh" contype="0" conaffinity="0" group="1" density="0" rgba="0.419608 0.419608 0.419608 1" mesh="right_shoulder_pitch_link"/>
        <body name="right_shoulder_roll_link" pos="0 -0.0588 0" quat="0.996195 0.0871543 0 0">
          <inertial pos="0.000132994 -0.00797311 -0.0452117" quat="0.996194 -0.0871554 -0.00108071 0.00011147" mass="1.126" diaginertia="0.00147896 0.00143616 0.000604056"/>
          <joint name="right_shoulder_roll_joint" pos="0 0 0" axis="1 0 0" range="-2.653 0.175" actuatorfrcrange="-14 14"/>
          <geom type="mesh" contype="0" conaffinity="0" group="1" density="0" rgba="1.43 1.43 1.43 1" mesh="right_shoulder_roll_link"/>
          <geom type="mesh" rgba="1.43 1.43 1.43 1" mesh="right_shoulder_roll_link"/>
          <body name="right_shoulder_yaw_link" pos="0 -0.018928 -0.10734" quat="0.996195 -0.0871543 0 0">
            <inertial pos="-0.0009376 0 -0.0773538" quat="0.999861 4.50062e-06 0.0166784 -0.000100443" mass="0.896" diaginertia="0.00233047 0.00227735 0.000685881"/>
            <joint name="right_shoulder_yaw_joint" pos="0 0 0" axis="0 0 1" range="-2.618 2.618" actuatorfrcrange="-14 14"/>
            <geom type="mesh" contype="0" conaffinity="0" group="1" density="0" rgba="1.43 1.43 1.43 1" mesh="right_shoulder_yaw_link"/>
            <geom type="mesh" rgba="1.43 1.43 1.43 1" mesh="right_shoulder_yaw_link"/>
            <body name="right_elbow_link" pos="0.01 0 -0.151">
              <inertial pos="0.0945565 -1.42e-06 -0.0109687" quat="0 0.726686 0 0.68697" mass="0.576" diaginertia="0.00169287 0.00166798 0.000367392"/>
              <joint name="right_elbow_joint" pos="0 0 0" axis="0 1 0" range="-0.873 1.571" actuatorfrcrange="-14 14"/>
              <geom type="mesh" contype="0" conaffinity="0" group="1" density="0" rgba="1.43 1.43 1.43 1" mesh="right_elbow_link"/>
              <geom type="mesh" rgba="1.43 1.43 1.43 1" mesh="right_elbow_link"/>
              <body name="right_wrist_roll_link" pos="0.201 0 -0.01" quat="0.996195 0.0871543 0 0">
                <inertial pos="0.0730257 0.00113159 0.00318964" quat="0.631654 0.276544 0.61318 0.385417" mass="0.93" diaginertia="0.000680774 0.000532489 0.000228916"/>
                <joint name="right_wrist_roll_joint" pos="0 0 0" axis="1 0 0" range="-2.662 2.662" actuatorfrcrange="-2.2 2.2"/>
                <geom type="mesh" contype="0" conaffinity="0" group="1" density="0" rgba="0.419608 0.419608 0.419608 1" mesh="right_wrist_roll_link"/>
                <geom type="mesh" rgba="0.419608 0.419608 0.419608 1" mesh="right_wrist_roll_link"/>
                <geom pos="0.015 0 0" quat="0.499998 0.5 0.500002 0.5" type="mesh" contype="0" conaffinity="0" group="1" density="0" rgba="1 1 1 1" mesh="right_base_link"/>
                <geom pos="0.015 0 0" quat="0.499998 0.5 0.500002 0.5" type="mesh" rgba="1 1 1 1" mesh="right_base_link"/>
                <body name="right_thumb_metacarpal_link" pos="0.0428251 0.0056191 0.0198669" quat="0.540156 0.456321 0.54016 0.456322">
                  <inertial pos="1.51106e-05 0.00707243 -0.00420847" quat="0.465075 -0.0302438 0.0586743 0.882807" mass="0.01" diaginertia="1.66115e-07 1.56006e-07 4.9387e-08"/>
                  <joint name="right_thumb_metacarpal_joint" pos="0 0 0" axis="0 0 -1" range="0 1.57" actuatorfrcrange="-0.5 0.5"/>
                  <geom type="mesh" contype="0" conaffinity="0" group="1" density="0" rgba="1 1 1 1" mesh="right_thumb_metacarpal_link"/>
                  <geom type="mesh" rgba="1 1 1 1" mesh="right_thumb_metacarpal_link"/>
                  <body name="right_thumb_proximal_link" pos="0 0.014227 0" quat="0.986557 0.0765206 0.124804 0.0726253">
                    <inertial pos="-4.6972e-07 0.0277015 -0.00202656" quat="0.496496 0.503512 -0.503514 0.496429" mass="0.05" diaginertia="2.56295e-06 2.40452e-06 5.11916e-07"/>
                    <joint name="right_thumb_proximal_joint" pos="0 0 0" axis="1 0 0" range="0 1.03" actuatorfrcrange="-1.1 1.1"/>
                    <geom type="mesh" contype="0" conaffinity="0" group="1" density="0" rgba="1 1 1 1" mesh="right_thumb_proximal_visual_link"/>
                    <geom type="mesh" rgba="1 1 1 1" mesh="right_thumb_proximal_link"/>
                    <body name="right_thumb_distal_link" pos="0 0.052 0">
                      <inertial pos="-6.86982e-09 0.0116258 5.41195e-05" quat="0.541201 0.455023 -0.454995 0.541328" mass="0.012" diaginertia="4.42525e-07 3.36691e-07 2.28409e-07"/>
                      <joint name="right_thumb_distal_joint" pos="0 0 0" axis="1 0 0" range="0 1.03" actuatorfrcrange="-1.1 1.1"/>
                      <geom type="mesh" contype="0" conaffinity="0" group="1" density="0" rgba="1 1 1 1" mesh="right_thumb_distal_link"/>
                      <geom type="mesh" rgba="1 1 1 1" mesh="right_thumb_distal_link"/>
                      <geom pos="0 0.013836 0.0076686" quat="0.99618 -0.0873286 0 0" type="mesh" contype="0" conaffinity="0" group="1" density="0" rgba="1 1 1 1" mesh="right_thumb_touch_link"/>
                      <geom pos="0 0.013836 0.0076686" quat="0.99618 -0.0873286 0 0" type="mesh" rgba="1 1 1 1" mesh="right_thumb_touch_link"/>
                    </body>
                  </body>
                </body>
                <body name="right_index_proximal_link" pos="0.0958761 -0.0021346 0.0295777" quat="0.524169 0.389611 0.550257 0.520257">
                  <inertial pos="-0.00223495 3.15875e-06 0.0176402" quat="0.9998 0.000578854 0.0200071 0.00015863" mass="0.009" diaginertia="2.52201e-07 2.36436e-07 9.27798e-08"/>
                  <joint name="right_index_proximal_joint" pos="0 0 0" axis="0 1 0" range="0 1.41" actuatorfrcrange="-2 2"/>
                  <geom type="mesh" contype="0" conaffinity="0" group="1" density="0" rgba="1 1 1 1" mesh="right_index_proximal_link"/>
                  <geom type="mesh" rgba="1 1 1 1" mesh="right_index_proximal_link"/>
                  <body name="right_index_distal_link" pos="0 0 0.032">
                    <inertial pos="0.00506251 1.61615e-07 0.0165189" quat="0.684726 0.176495 0.176496 0.684726" mass="0.011" diaginertia="7.85555e-07 7.71534e-07 8.73346e-08"/>
                    <joint name="right_index_distal_joint" pos="0 0 0" axis="0 1 0" range="0 1.63" actuatorfrcrange="-2 2"/>
                    <geom type="mesh" contype="0" conaffinity="0" group="1" density="0" rgba="1 1 1 1" mesh="right_index_distal_link"/>
                    <geom type="mesh" rgba="1 1 1 1" mesh="right_index_distal_link"/>
                    <geom pos="0.014497 0 0.023303" quat="0.6361 0.734769 0.154182 -0.178098" type="mesh" contype="0" conaffinity="0" group="1" density="0" rgba="1 1 1 1" mesh="right_index_touch_link"/>
                    <geom pos="0.014497 0 0.023303" quat="0.6361 0.734769 0.154182 -0.178098" type="mesh" rgba="1 1 1 1" mesh="right_index_touch_link"/>
                  </body>
                </body>
                <body name="right_middle_proximal_link" pos="0.0999931 -0.00457639 0.0100507" quat="0.483516 0.438557 0.540603 0.530688">
                  <inertial pos="-0.00222511 5.25632e-06 0.0203008" quat="0.999816 0.00054813 0.0191911 0.000563992" mass="0.009" diaginertia="3.67373e-07 3.52646e-07 1.11857e-07"/>
                  <joint name="right_middle_proximal_joint" pos="0 0 0" axis="0 1 0" range="0 1.41" actuatorfrcrange="-2 2"/>
                  <geom type="mesh" contype="0" conaffinity="0" group="1" density="0" rgba="1 1 1 1" mesh="right_middle_proximal_link"/>
                  <geom type="mesh" rgba="1 1 1 1" mesh="right_middle_proximal_link"/>
                  <body name="right_middle_distal_link" pos="0 0 0.037">
                    <inertial pos="0.00591597 -2.75379e-08 0.0190796" quat="0.6873 0.166308 0.166321 0.687239" mass="0.011" diaginertia="1.06828e-06 1.04938e-06 1.11406e-07"/>
                    <joint name="right_middle_distal_joint" pos="0 0 0" axis="0 1 0" range="0 1.63" actuatorfrcrange="-2 2"/>
                    <geom type="mesh" contype="0" conaffinity="0" group="1" density="0" rgba="1 1 1 1" mesh="right_middle_distal_link"/>
                    <geom type="mesh" rgba="1 1 1 1" mesh="right_middle_distal_link"/>
                    <geom pos="0.0159759 0 0.0265894" quat="0.971858 0 0.235566 0" type="mesh" contype="0" conaffinity="0" group="1" density="0" rgba="1 1 1 1" mesh="right_middle_touch_link"/>
                    <geom pos="0.0159759 0 0.0265894" quat="0.971858 0 0.235566 0" type="mesh" rgba="1 1 1 1" mesh="right_middle_touch_link"/>
                  </body>
                </body>
                <body name="right_ring_proximal_link" pos="0.098982 -0.00467059 -0.0100263" quat="0.438844 0.483813 0.53045 0.540337">
                  <inertial pos="-0.00234495 5.87955e-06 0.0191774" quat="0.999831 0.000632097 0.0183324 0.000717657" mass="0.009" diaginertia="3.14463e-07 2.97613e-07 1.01829e-07"/>
                  <joint name="right_ring_proximal_joint" pos="0 0 0" axis="0 1 0" range="0 1.41" actuatorfrcrange="-2 2"/>
                  <geom type="mesh" contype="0" conaffinity="0" group="1" density="0" rgba="1 1 1 1" mesh="right_ring_proximal_link"/>
                  <geom type="mesh" rgba="1 1 1 1" mesh="right_ring_proximal_link"/>
                  <body name="right_ring_distal_link" pos="0 0 0.035">
                    <inertial pos="0.00570078 5.57858e-08 0.0185997" quat="0.686867 0.167968 0.167968 0.686867" mass="0.011" diaginertia="1.01271e-06 9.96672e-07 1.02706e-07"/>
                    <joint name="right_ring_distal_joint" pos="0 0 0" axis="0 1 0" range="0 1.63" actuatorfrcrange="-2 2"/>
                    <geom type="mesh" contype="0" conaffinity="0" group="1" density="0" rgba="1 1 1 1" mesh="right_ring_distal_link"/>
                    <geom type="mesh" rgba="1 1 1 1" mesh="right_ring_distal_link"/>
                    <geom pos="0.0154392 0 0.0260561" quat="0.971858 0 0.235566 0" type="mesh" contype="0" conaffinity="0" group="1" density="0" rgba="1 1 1 1" mesh="right_ring_touch_link"/>
                    <geom pos="0.0154392 0 0.0260561" quat="0.971858 0 0.235566 0" type="mesh" rgba="1 1 1 1" mesh="right_ring_touch_link"/>
                  </body>
                </body>
                <body name="right_pinky_proximal_link" pos="0.0936939 -0.00235631 -0.0293663" quat="0.390267 0.52487 0.519764 0.549589">
                  <inertial pos="-0.00213212 7.75039e-06 0.0160672" quat="0.999803 0.000555178 0.0198191 0.000562874" mass="0.009" diaginertia="1.97745e-07 1.82023e-07 8.19805e-08"/>
                  <joint name="right_pinky_proximal_joint" pos="0 0 0" axis="0 1 0" range="0 1.41" actuatorfrcrange="-2 2"/>
                  <geom type="mesh" contype="0" conaffinity="0" group="1" density="0" rgba="1 1 1 1" mesh="right_pinky_proximal_link"/>
                  <geom type="mesh" rgba="1 1 1 1" mesh="right_pinky_proximal_link"/>
                  <body name="right_pinky_distal_link" pos="0 0 0.029">
                    <inertial pos="0.00473738 -1.62934e-07 0.0150053" quat="0.682052 0.186478 0.186456 0.682103" mass="0.011" diaginertia="6.20818e-07 6.07614e-07 8.1918e-08"/>
                    <joint name="right_pinky_distal_joint" pos="0 0 0" axis="0 1 0" range="0 1.63" actuatorfrcrange="-2 2"/>
                    <geom type="mesh" contype="0" conaffinity="0" group="1" density="0" rgba="1 1 1 1" mesh="right_pinky_distal_link"/>
                    <geom type="mesh" rgba="1 1 1 1" mesh="right_pinky_distal_link"/>
                    <geom pos="0.01401 0 0.021124" quat="0.971859 0 0.235565 0" type="mesh" contype="0" conaffinity="0" group="1" density="0" rgba="1 1 1 1" mesh="right_pinky_touch_link"/>
                    <geom pos="0.01401 0 0.021124" quat="0.971859 0 0.235565 0" type="mesh" rgba="1 1 1 1" mesh="right_pinky_touch_link"/>
                  </body>
                </body>
              </body>
            </body>
          </body>
        </body>
      </body>
    </body>
  </worldbody>


<actuator>
    <motor name="left_hip_yaw_joint" joint="left_hip_yaw_joint"/>
    <motor name="left_hip_roll_joint" joint="left_hip_roll_joint"/>
    <motor name="left_hip_pitch_joint" joint="left_hip_pitch_joint"/>
    <motor name="left_knee_joint" joint="left_knee_joint"/>
    <motor name="left_ankle_pitch_joint" joint="left_ankle_pitch_joint"/>
    <motor name="left_ankle_roll_joint" joint="left_ankle_roll_joint"/>-->
    <motor name="right_hip_yaw_joint" joint="right_hip_yaw_joint"/>
    <motor name="right_hip_roll_joint" joint="right_hip_roll_joint"/>
    <motor name="right_hip_pitch_joint" joint="right_hip_pitch_joint"/>
    <motor name="right_knee_joint" joint="right_knee_joint"/>
    <motor name="right_ankle_pitch_joint" joint="right_ankle_pitch_joint"/>
    <motor name="right_ankle_roll_joint" joint="right_ankle_roll_joint"/>-->


    <motor name="left_shoulder_pitch_joint" joint="left_shoulder_pitch_joint"/>
    <motor name="left_shoulder_roll_joint" joint="left_shoulder_roll_joint"/>
    <motor name="left_shoulder_yaw_joint" joint="left_shoulder_yaw_joint"/>
    <motor name="left_elbow_joint" joint="left_elbow_joint"/>
    <motor name="left_wrist_roll_joint" joint="left_wrist_roll_joint"/>

    <motor name="right_shoulder_pitch_joint" joint="right_shoulder_pitch_joint"/>
    <motor name="right_shoulder_roll_joint" joint="right_shoulder_roll_joint"/>
    <motor name="right_shoulder_yaw_joint" joint="right_shoulder_yaw_joint"/>
    <motor name="right_elbow_joint" joint="right_elbow_joint"/>
    <motor name="right_wrist_roll_joint" joint="right_wrist_roll_joint"/>

  </actuator>

</mujoco>
